Workbook
Name EP_001: #REF!

Sheet Introduction
B1: Inspection and Test Plan
B3: Project Name | D3: Hessay | I3: Project Number | K3: EC006
B4: Prepared By | D4: Harry Crabb | I4: Approved By
B5: Revision | D5: 0.1 | I5: Date | K5: 46183
B6: SOLAR
B8: 01 Initial Site and Fencing
B10: 02 Trenching and Cables
B12: 03 Foundation Construction
B14: 04 Drainage
B16: 05 CCTV
B18: 06 Mounting Structure
B20: 07 Inverter and Isolator
B22: 08 Meteo and Weather Station
B24: 09 Transformer Station

Sheet 01 Initial Site and Fencing
A3: Inspection and Test Plan | J3: Witness (W) - Opporunity shall be given to the required representatives to witness the works. Works can commence if no representative is present at the informed time Hold (H) - Works shall not proceed until works are witnessed by the required representatives Surveillance (S) - Works commence and will be witnessed on an ad-hoc basis
A4: Project Name | D4: =Introduction!D3 -> Hessay | F4: Project Number | I4: =Introduction!K3 -> EC006
A5: ITP Scope | D5: =Introduction!B6 -> SOLAR
A7: Ref | B7: Phase P = Pre works M = Material C = Construction | C7: Element | D7: Inspection/Test Description | E7: Responsibility for Completion | F7: Witness | I7: Standard/Pass Criteria V = Visual DI = Dimension P = As per Project Drawings / Design TPI = Third Party Inspection T= Test | J7: Evidence/Required Documentation | K7: Frequency | L7: Quantity for Project | M7: Post Inspection/Test | P7: file location (hyperlink) | Q7: Uploaded to SharePoint
F8: EPC | G8: Client | H8: DNO | M8: Completed By | N8: Date | O8: Pass/Fail
A9: Compound Hardstanding
A10: 1 | B10: P | C10: Design review | D10: Confirmation design layout meets ERs and planning requirements under the EPC contract. | E10: Ethical Power | F10: H | I10: P | J10: IFC drawings to be issued | K10: Each IFC drawing
A11: 2 | B11: M | C11: Material review | D11: Inspection and confirmation that materials meet the design specification. | E11: Contractor | F11: W | I11: P MCHW 600 & 800 Series, BS EN 13242 | J11: Material datasheets Material safety datasheets (if applicable) Material grading certificates EP-ITD-00-01 Material Delivery | K11: All procured material
A12: 3 | B12: M | C12: Material delivery inspection | D12: Confirmation that delivered material conforms to the design specification and the supplied documentation. | E12: Contractor | F12: W | I12: P,V MCHW 600 & 800 Series, BS EN 13242 | J12: EP-ITD-00-01 Material delivery | K12: Each delivery of material
A13: 4 | B13: C | C13: Setting out | D13: Inspection and confirmation of setting out. | E13: Contractor | F13: W | I13: P,DI | J13: EP-ITD-01-01 Setting out | K13: Each compound area
A14: 5 | B14: C | C14: CBR testing | D14: CBR ground testing | E14: Contractor | F14: H | I14: TPI,P | J14: CBR test certificates | K14: 1 test every 25m2
A15: 6 | B15: C | C15: Compound Construction | D15: Inspection and confirmation of compound construction | E15: Contractor | F15: W | I15: V,DI MCHW 600 & 800 Series, BS EN 13242 | J15: EP-ITD-01-02 Access Track/Compound Construction | K15: 1 Inspection every 25m2
A16: 7 | B16: C | C16: Final dimensions and levels | D16: Site engineer to take final dimension and level records | E16: Contractor | F16: S | I16: DI | J16: Site engineer DWG files | K16: Each compound area
A17: 8 | B17: C | C17: Redline & As-Built records | D17: Handover of all redline marked up drawins to be added to as-built designs | E17: Contractor | F17: H | I17: P | J17: RL drawings | K17: Each design
A18: Access Tracks
A19: 1 | B19: P | C19: Design review | D19: Confirmation design layout meets ERs and planning requirements under the EPC contract. | E19: Ethical Power | F19: H | I19: P | J19: IFC drawings to be issued | K19: Each IFC drawing
A20: 2 | B20: M | C20: Material review | D20: Inspection and confirmation that materials meet the design specification. | E20: Contractor | F20: W | I20: P MCHW 600 & 800 Series, BS EN 13242 | J20: Material datasheets Material safety datasheets (if applicable) Material grading certificates EP-ITD-00-01 Material Delivery | K20: All procured material
A21: 3 | B21: M | C21: Material delivery inspection | D21: Confirmation that delivered material conforms to the design specification and the supplied documentation. | E21: Contractor | F21: W | I21: P,V MCHW 600 & 800 Series, BS EN 13242 | J21: EP-ITD-00-01 Material delivery | K21: Each delivery of material
A22: 4 | B22: C | C22: Setting out | D22: Inspection and confirmation of setting out. | E22: Contractor | F22: W | I22: P,DI | J22: EP-ITD-01-01 Setting out | K22: Each compound area
A23: 5 | B23: C | C23: CBR testing | D23: CBR ground testing | E23: Contractor | F23: H | I23: TPI,P | J23: CBR test certificates | K23: 1 test every 50m of track
A24: 6 | B24: C | C24: Compound Construction | D24: Inspection and confirmation of compound construction | E24: Contractor | F24: W | I24: V,DI MCHW 600 & 800 Series, BS EN 13242 | J24: EP-ITD-01-02 Access Track/Compound Construction | K24: 1 inspection for every 250m of access track
A25: 7 | B25: C | C25: Final dimensions and levels | D25: Site engineer to take final dimension and level records | E25: Contractor | F25: S | I25: DI | J25: Site engineer DWG files | K25: Each compound area
A26: 8 | B26: C | C26: Redline & As-Built records | D26: Handover of all redline marked up drawins to be added to as-built designs | E26: Contractor | F26: H | I26: P | J26: RL drawings | K26: Each design
A27: Deer Fencing and Gates
A28: 1 | B28: P | C28: Design review | D28: Confirmation design layout meets ERs and planning requirements under the EPC contract. | E28: Ethical Power | F28: H | I28: P | J28: IFC drawings to be issued | K28: Each IFC drawing
A29: 2 | B29: M | C29: Material review | D29: Inspection and confirmation that materials meet the design specification. | E29: Contractor | F29: W | I29: P | J29: Material datasheets Material safety datasheets (if applicable) EP-ITD-00-01 Material Delivery | K29: All procured material
A30: 3 | B30: C | C30: Setting out | D30: Inspection and confirmation of setting out. | E30: Contractor | F30: W | I30: P,DI | J30: EP-ITD-01-01 Setting out | K30: Each field fence line
A31: 4 | B31: C | C31: Deer fencing installation | D31: Inspection of deer fencing installation | E31: Contractor | F31: S | I31: P,DI | J31: EP-ITD-01-04 Deer Fencing inspection | K31: Every 500m fence line
A32: 5 | B32: C | C32: Access gate installation | D32: Inspection of access gate installation | E32: Contractor | F32: S | I32: P,DI | J32: EP-ITD-01-05 Access Gate inspection | K32: Each access gate

Sheet 02 Trenching and Cables
A3: Inspection and Test Plan | J3: Witness (W) - Opporunity shall be given to the required representatives to witness the works. Works can commence if no representative is present at the informed time Hold (H) - Works shall not proceed until works are witnessed by the required representatives Surveillance (S) - Works commence and will be witnessed on an ad-hoc basis
A4: Project Name | D4: =Introduction!D3 -> Hessay | F4: Project Number | I4: =Introduction!K3 -> EC006
A5: ITP Scope | D5: =Introduction!B6 -> SOLAR
A7: Ref | B7: Phase P = Pre works M = Material C = Construction | C7: Element | D7: Inspection/Test Description | E7: Responsibility for Completion | F7: Witness | I7: Standard/Pass Criteria V = Visual DI = Dimension P = As per Project Drawings / Design TPI = Third Party Inspection T= Test | J7: Evidence/Required Documentation | K7: Frequency | L7: Quantity for Project | M7: Post Inspection/Test | P7: file location (hyperlink) | Q7: Uploaded to SharePoint
F8: EPC | G8: Client | H8: DNO | M8: Completed By | N8: Date | O8: Pass/Fail
A9: Cable trenching (ducted)
A10: 1 | B10: P | C10: Confirmation of trench route design | D10: IFC drawings issued for trench route and elevations | E10: EP | I10: P | J10: IFC Frawings
A11: 2 | B11: M | C11: Material documentation | D11: Material documentation for - Ducts - Chambers - Cable - Connectors | E11: Contractor | F11: W | I11: V | J11: Material datasheets Safety datasheets Factory acceptance test documents Delivery notes EP-ITD-00-01 Material Delivery | K11: All procured material
A12: 3 | B12: C | C12: Pre-installation cable testing | D12: Cable sheath/IR testing prior to installation | E12: Contractor | F12: H | I12: V,T | J12: Test certificates | K12: Each cable drum (AC LV, HV)
A13: 4 | B13: C | C13: Setting out | D13: Confirmation of setting out activities | E13: Contractor | F13: H | I13: V,DI | J13: EP-ITD-01-01 Setting out | K13: Complete trench route
A14: 5 | B14: C | C14: Trench installation inspection | D14: Confirmation of trenching and duct installation | E14: Contractor | F14: W | I14: V,DI | J14: EP-ITD-02-01 Duct Trench installation | K14: 1 inspection to be completed for every 150m of trench
A15: 6 | B15: C | C15: Redline & As-Built records | D15: Handover of all redline marked up drawins to be added to as-built designs | E15: Contractor | F15: H | I15: P | J15: RL drawings | K15: Each trench route
A16: Cable trenching (direct burial)
A17: 1 | B17: P | C17: Confirmation of trench route design | D17: IFC drawings issued for trench route and elevations | E17: EP | I17: P | J17: IFC Frawings
A18: 2 | B18: M | C18: Material documentation | D18: Material documentation for - Ducts - Chambers - Cable - Connectors | E18: Contractor | F18: W | I18: V | J18: Material datasheets Safety datasheets Factory acceptance test documents Delivery notes EP-ITD-00-01 Material Delivery | K18: All procured material
A19: 3 | B19: C | C19: Pre-installation cable testing | D19: Cable sheath/IR testing prior to installation | E19: Contractor | F19: H | I19: V,T | J19: Test certificates | K19: Each cable drum (AC LV, HV)
A20: 4 | B20: C | C20: Setting out | D20: Confirmation of setting out activities | E20: Contractor | F20: H | I20: V,DI | J20: EP-ITD-01-01 Setting out | K20: Complete trench route
A21: 5 | B21: C | C21: Trench installation inspection | D21: Confirmation of trenching and duct installation | E21: Contractor | F21: W | I21: V,DI | J21: EP-ITD-02-06 Direct burial Trench installation | K21: 1 inspection to be completed for every 150m of trench
A22: 6 | B22: C | C22: Redline & As-Built records | D22: Handover of all redline marked up drawins to be added to as-built designs | E22: Contractor | F22: H | I22: P | J22: RL drawings | K22: Each trench route
A23: Cable trenching (HV)
A24: 1 | B24: P | C24: Confirmation of trench route design | D24: IFC drawings issued for trench route and elevations | E24: EP | I24: P | J24: IFC Frawings
A25: 2 | B25: M | C25: Material documentation | D25: Material documentation for - Ducts - Chambers - Cable - Connectors | E25: Contractor | F25: W | I25: V | J25: Material datasheets Safety datasheets Factory acceptance test documents Delivery notes EP-ITD-00-01 Material Delivery | K25: All procured material
A26: 3 | B26: C | C26: Pre-installation cable testing | D26: Cable sheath/IR testing prior to installation | E26: Contractor | F26: H | I26: V,T | J26: Test certificates | K26: Each cable drum (AC LV, HV)
A27: 4 | B27: C | C27: Setting out | D27: Confirmation of setting out activities | E27: Contractor | F27: H | I27: V,DI | J27: EP-ITD-01-01 Setting out | K27: Complete trench route
A28: 5 | B28: C | C28: Trench installation inspection | D28: Confirmation of trenching and duct installation | E28: Contractor | F28: W | I28: V,DI | J28: EP-ITD-02-06 Direct burial Trench installation | K28: Every 100m of trench
A29: 6 | B29: C | C29: HV Cable pull inspection | D29: Monitoring and inspection of HV cable pull | E29: Contractor | F29: W | I29: V,DI | J29: EP-ITD-08-01 HV Cable installation | K29: 1 inspection to be completed for every 150m of trench
A30: 7 | B30: C | C30: HV Cable joint inspection (if required) | D30: Inspection of HV Cable joint | E30: Contractor | F30: H | I30: V | J30: EP-ITD-08-05 Jointing termination record | K30: 1 inspection for each joint or termination
A31: 8 | B31: C | C31: Redline & As-Built records | D31: Handover of all redline marked up drawins to be added to as-built designs | E31: Contractor | F31: H | I31: P | J31: RL drawings | K31: Each trench route
A32: Earthing
A33: 1 | B33: P | C33: Confirmation of trench route design | D33: IFC drawings issued for trench route and elevations | E33: EP | I33: P | J33: IFC Frawings
A34: 2 | B34: M | C34: Material documentation | D34: Material documentation for - Cable - Crimps - Rods - Bolted connectors | E34: Contractor | F34: W | I34: V | J34: Material datasheets Safety datasheets Factory acceptance test documents Delivery notes EP-ITD-00-01 Material Delivery | K34: All procured material
A35: 4 | B35: C | C35: Setting out | D35: Confirmation of setting out activities | E35: Contractor | F35: H | I35: V,DI | J35: EP-ITD-01-01 Setting out | K35: Complete trench route
A36: 5 | B36: C | C36: Trench installation inspection | D36: Confirmation of trenching and duct installation | E36: Contractor | F36: W | I36: V,DI | J36: EP-ITD-02-06 Direct burial Trench installation | K36: 1 inspection to be completed for every 150m of trench
A37: 6 | B37: C | C37: Exothermic/CAD Welding (where required) | D37: Inspection of exothermic welded connection | E37: Contractor | F37: W | I37: V | J37: EP-ITD-05-02 Exothermic weld inspection | K37: Each welded connection
A38: 7 | B38: C | C38: Ductor test | D38: Ductor test for continuity across earth joints | E38: Contractor | F38: W | I38: T | J38: Photogrpahic evidence / test document | K38: Each connection
A39: 8 | B39: C | C39: Redline & As-Built records | D39: Handover of all redline marked up drawins to be added to as-built designs | E39: Contractor | F39: H | I39: P | J39: RL drawings | K39: Each trench route
A40: Joint Bay
A41: 1 | B41: P | C41: Confirmation of trench route design | D41: IFC drawings issued for trench route and elevations | E41: EP | I41: P | J41: IFC Frawings
A42: 2 | B42: M | C42: Material documentation | D42: Material documentation for - Cable - Joint Kits - Tooling | E42: Contractor | F42: W | I42: V | J42: Material datasheets Safety datasheets Factory acceptance test documents Delivery notes EP-ITD-00-01 Material Delivery | K42: All procured material
A43: 3 | B43: C | C43: Setting out | D43: Confirmation of setting out activities | E43: Contractor | F43: H | I43: V,DI | J43: EP-ITD-01-01 Setting out | K43: Complete trench route
...

Sheet 03 Foundation Construction
A3: Inspection and Test Plan | J3: Witness (W) - Opporunity shall be given to the required representatives to witness the works. Works can commence if no representative is present at the informed time Hold (H) - Works shall not proceed until works are witnessed by the required representatives Surveillance (S) - Works commence and will be witnessed on an ad-hoc basis
A4: Project Name | D4: =Introduction!D3 -> Hessay | F4: Project Number | I4: =Introduction!K3 -> EC006
A5: ITP Scope | D5: =Introduction!B6 -> SOLAR
A7: Ref | B7: Phase P = Pre works M = Material C = Construction | C7: Element | D7: Inspection/Test Description | E7: Responsibility for Completion | F7: Witness | I7: Standard/Pass Criteria V = Visual DI = Dimension P = As per Project Drawings / Design TPI = Third Party Inspection T= Test | J7: Evidence/Required Documentation | K7: Frequency | L7: Quantity for Project | M7: Post Inspection/Test | P7: file location (hyperlink) | Q7: Uploaded to SharePoint
F8: EPC | G8: Client | H8: DNO | M8: Completed By | N8: Date | O8: Pass/Fail
A9: STS (MV Station) Foundations
A10: 1 | B10: P | C10: Design review | D10: Confirmation design layout meets ERs and planning requirements under the EPC contract. | E10: Ethical Power | F10: H | I10: P | J10: IFC drawings to be issued | K10: Each IFC drawing
A11: 2 | B11: M | C11: Material review | D11: Inspection and confirmation that materials meet the design specification. - Reinforcement bars - Waterstop materials - Set in materials (pipework, ducting) - Earthing materials - Chambers | E11: Contractor | F11: W | I11: P EP-1528-STS-FS-1 | J11: Material datasheets Material safety datasheets (if applicable) Material grading certificates | K11: All procured material
A12: 3 | B12: M | C12: Material delivery inspection | D12: Confirmation that delivered material conforms to the design specification and the supplied documentation. - Reinforcement bars - Waterstop materials - Set in materials (pipework, ducting) - Earthing materials - Chambers | E12: Contractor | F12: W | I12: P,V | J12: EP-ITD-00-01 Material delivery | K12: Each delivery of material
A13: 4 | B13: C | C13: Setting out | D13: Inspection and confirmation of setting out activities | E13: Contractor | F13: W | I13: P,DI | J13: EP-ITD-01-01 Setting out | K13: Each foundation
A14: 5 | B14: C | C14: Excavation | D14: Confirmation of excavation condition and preparation | E14: Contractor | F14: W | I14: V,DI | J14: EP-ITD-01-07 Excavation/Earthworks | K14: 1 inspection for each excavation
A15: 6 | B15: C | C15: Formation level CBR testing | D15: CBR testing at formation level to confirm ground conditions meet minimum requirements for design installation | E15: Contractor | F15: H | I15: TPI BS 1377-9: 2002 | J15: CBR test certificates | K15: Each foundation excavation
A16: 7 | B16: C | C16: Pre pour inspection | D16: Confirmation of dimensions, reinfocement bar positioning, formwork condition, oiling/greasing, set in components, earthing | E16: Contractor | F16: W | I16: V,DI | J16: EP-ITD-04-01 Pre Pour check | K16: Each concrete pour
A17: 8 | B17: C | C17: Pour monitoring | D17: Confirmation of concrete specification, delivery documentation, weather conditions, pour progress, finish | E17: Contractor | F17: W | I17: V | J17: EP-ITD-04-02 Pour monitoring | K17: Each concrete pour
A18: 9 | B18: C | C18: Cube and Slump testing | D18: Complete slump test of delivered concrete to confirm conformance with design. Create concrete cubes for testing | E18: Contractor | F18: W | I18: V,TPI Standard pass for slump. Cubes to be formed BS EN 12390-3:2019 for compressive strength tests Slump test BS EN 12350-2 | K18: 1 slump per pour 4 test cubes (7 days, 14 days, 28 days, spare)
A19: 10 | B19: C | C19: Post pour inspection | E19: Contractor | F19: W | I19: V,DI | J19: EP-ITD-04-03 Post Pour check | K19: Each concrete pour
A20: 11 | B20: C | C20: Cube test results | D20: Confirmation concrete strength meets design requirements | E20: Contractor | F20: W | I20: TPI Cubes to be formed BS EN 12390-3:2019 for compressive strength tests Slump test BS EN 12350-2 | J20: Cube test certificates (UKAS test lab) | K20: 4 test cubes (7 days, 14 days, 28 days, spare)
A21: 12 | B21: C | C21: Oil catchment bund sealant | D21: Application and inspection of oil catchment bund expoy sealant | E21: Contractor | F21: W | I21: V | J21: Photo evidence | K21: Each bund
A22: 13 | B22: C | C22: Oil catchment bund leak test | D22: Oil catchment bund leak test | E22: Contractor | F22: W | I22: V | J22: EP-ITD-03-03 Transformer bund leak test | K22: Test for each bund
A23: 14 | B23: C | C23: Redline & As-Built records | D23: Handover of all redline marked up drawins to be added to as-built designs | E23: Contractor | F23: H | I23: P | J23: RL drawings | K23: Each design
A24: CSS Foundation
A25: 1 | B25: P | C25: Design review | D25: Confirmation design layout meets ERs and planning requirements under the EPC contract. | E25: Ethical Power | F25: H | I25: P | J25: IFC drawings to be issued | K25: Each IFC drawing
A26: 2 | B26: M | C26: Material review | D26: Inspection and confirmation that materials meet the design specification. - Reinforcement bars - Waterstop materials - Set in materials (pipework, ducting) - Earthing materials - Chambers | E26: Contractor | F26: W | I26: P EP-1528-STS-FS-1 | J26: Material datasheets Material safety datasheets (if applicable) Material grading certificates | K26: All procured material
A27: 3 | B27: M | C27: Material delivery inspection | D27: Confirmation that delivered material conforms to the design specification and the supplied documentation. - Reinforcement bars - Waterstop materials - Set in materials (pipework, ducting) - Earthing materials - Chambers | E27: Contractor | F27: W | I27: P,V | J27: EP-ITD-00-01 Material delivery | K27: Each delivery of material
A28: 4 | B28: C | C28: Setting out | D28: Inspection and confirmation of setting out activities | E28: Contractor | F28: W | I28: P,DI | J28: EP-ITD-01-01 Setting out | K28: Each foundation
A29: 5 | B29: C | C29: Excavation | D29: Confirmation of excavation condition and preparation | E29: Contractor | F29: W | I29: V,DI | J29: EP-ITD-01-07 Excavation/Earthworks | K29: 1 inspection for each excavation
A30: 6 | B30: C | C30: Formation level CBR testing | D30: CBR testing at formation level to confirm ground conditions meet minimum requirements for design installation | E30: Contractor | F30: H | I30: TPI BS 1377-9: 2002 | J30: CBR test certificates | K30: Each foundation excavation
A31: 7 | B31: C | C31: Pre pour inspection | D31: Confirmation of dimensions, reinfocement bar positioning, formwork condition, oiling/greasing, set in components, earthing | E31: Contractor | F31: W | I31: V,DI | J31: EP-ITD-04-01 Pre Pour check | K31: Each concrete pour
A32: 8 | B32: C | C32: Pour monitoring | D32: Confirmation of concrete specification, delivery documentation, weather conditions, pour progress, finish | E32: Contractor | F32: W | I32: V | J32: EP-ITD-04-02 Pour monitoring | K32: Each concrete pour
A33: 9 | B33: C | C33: Cube and Slump testing | D33: Complete slump test of delivered concrete to confirm conformance with design. Create concrete cubes for testing | E33: Contractor | F33: W | I33: V,TPI Standard pass for slump. Cubes to be formed BS EN 12390-3:2019 for compressive strength tests Slump test BS EN 12350-2 | K33: 1 slump per pour 4 test cubes (7 days, 14 days, 28 days, spare)
A34: 10 | B34: C | C34: Post pour inspection | D34: Confirmation of dimensions, concrete finish, levels, line, set in components | E34: Contractor | F34: W | I34: V,DI | J34: EP-ITD-04-03 Post Pour check | K34: Each concrete pour
A35: 11 | B35: C | C35: Cube test results | D35: Confirmation concrete strength meets design requirements | E35: Contractor | F35: W | I35: TPI Cubes to be formed BS EN 12390-3:2019 for compressive strength tests Slump test BS EN 12350-2 | J35: Cube test certificates (UKAS test lab) | K35: 4 test cubes (7 days, 14 days, 28 days, spare)
A36: 12 | B36: C | C36: Redline & As-Built records | D36: Handover of all redline marked up drawins to be added to as-built designs | E36: Contractor | F36: H | I36: P | J36: RL drawings | K36: Each design
A37: Minor Foundations
A38: 1 | B38: P | C38: Design review | D38: Confirmation design layout meets ERs and planning requirements under the EPC contract. | E38: Ethical Power | F38: H | I38: P | J38: IFC drawings to be issued | K38: Each IFC drawing
A39: 2 | B39: M | C39: Material review | D39: Inspection and confirmation that materials meet the design specification. - Reinforcement bars - Waterstop materials - Set in materials (pipework, ducting) - Earthing materials - Chambers | E39: Contractor | F39: W | I39: P EP-1528-STS-FS-1 | J39: Material datasheets Material safety datasheets (if applicable) Material grading certificates | K39: All procured material
A40: 3 | B40: M | C40: Material delivery inspection | D40: Confirmation that delivered material conforms to the design specification and the supplied documentation. - Reinforcement bars - Waterstop materials - Set in materials (pipework, ducting) - Earthing materials - Chambers | E40: Contractor | F40: W | I40: P,V | J40: EP-ITD-00-01 Material delivery | K40: Each delivery of material
A41: 4 | B41: C | C41: Setting out | D41: Inspection and confirmation of setting out activities | E41: Contractor | F41: W | I41: P,DI | J41: EP-ITD-01-01 Setting out | K41: Each foundation
A42: 5 | B42: C | C42: Excavation | D42: Confirmation of excavation condition and preparation | E42: Contractor | F42: W | I42: V,DI | J42: EP-ITD-01-07 Excavation/Earthworks | K42: 1 inspection for each excavation
A43: 6 | B43: C | C43: Post pour inspection | E43: Contractor | F43: W | I43: V,DI | J43: EP-ITD-04-03 Post Pour check | K43: Each concrete pour
...

Sheet 04 Drainage
A3: Inspection and Test Plan | J3: Witness (W) - Opporunity shall be given to the required representatives to witness the works. Works can commence if no representative is present at the informed time Hold (H) - Works shall not proceed until works are witnessed by the required representatives Surveillance (S) - Works commence and will be witnessed on an ad-hoc basis
A4: Project Name | D4: =Introduction!D3 -> Hessay | F4: Project Number | I4: =Introduction!K3 -> EC006
A5: ITP Scope | D5: =Introduction!B6 -> SOLAR
A7: Ref | B7: Phase P = Pre works M = Material C = Construction | C7: Element | D7: Inspection/Test Description | E7: Responsibility for Completion | F7: Witness | I7: Standard/Pass Criteria V = Visual DI = Dimension P = As per Project Drawings / Design TPI = Third Party Inspection T= Test | J7: Evidence/Required Documentation | K7: Frequency | L7: Quantity for Project | M7: Post Inspection/Test | P7: file location (hyperlink) | Q7: Uploaded to SharePoint
F8: EPC | G8: Client | H8: DNO | M8: Completed By | N8: Date | O8: Pass/Fail
A9: Trench filter drain
A10: 1 | B10: P | C10: Confirmation of trench route design | D10: IFC drawings issued for trench route and elevations | E10: EP | I10: P | J10: IFC Frawings
A11: 2 | B11: M | C11: Material documentation | D11: Material documentation for - Ducts - Chambers - Connectors | E11: Contractor | F11: W | I11: V | J11: Material datasheets Safety datasheets Delivery notes EP-ITD-00-01 Material Delivery | K11: All procured material
A12: 4 | B12: C | C12: Setting out | D12: Confirmation of setting out activities | E12: Contractor | F12: H | I12: V,DI | J12: EP-ITD-01-01 Setting out | K12: Complete trench route
A13: 5 | B13: C | C13: Drain installation inspection | D13: Confirmation of trenching and duct installation | E13: Contractor | F13: W | I13: V,DI | J13: EP-ITD-03-01 Drainage | K13: Every 150m of trench
A14: 6 | B14: C | C14: Manhole/Chamber inspection | D14: Confirmation of manhole installation as per designs | E14: Contractor | F14: W | I14: V,DI | J14: EP-ITD-03-02 Manhole | K14: Each manhole
A15: 7 | B15: C | C15: Redline & As-Built records | D15: Handover of all redline marked up drawins to be added to as-built designs | E15: Contractor | F15: H | I15: P | J15: RL drawings | K15: Each trench route

Sheet 05 CCTV
A3: Inspection and Test Plan | J3: Witness (W) - Opporunity shall be given to the required representatives to witness the works. Works can commence if no representative is present at the informed time Hold (H) - Works shall not proceed until works are witnessed by the required representatives Surveillance (S) - Works commence and will be witnessed on an ad-hoc basis
A4: Project Name | D4: =Introduction!D3 -> Hessay | F4: Project Number | I4: =Introduction!K3 -> EC006
A5: ITP Scope | D5: =Introduction!B6 -> SOLAR
A7: Ref | B7: Phase P = Pre works M = Material C = Construction | C7: Element | D7: Inspection/Test Description | E7: Responsibility for Completion | F7: Witness | I7: Standard/Pass Criteria V = Visual DI = Dimension P = As per Project Drawings / Design TPI = Third Party Inspection T= Test | J7: Evidence/Required Documentation | K7: Frequency | L7: Quantity for Project | M7: Post Inspection/Test | P7: file location (hyperlink) | Q7: Uploaded to SharePoint
F8: EPC | G8: Client | H8: DNO | M8: Completed By | N8: Date | O8: Pass/Fail
A9: CCTV Camera
A10: 1 | B10: P | C10: Design review | D10: Confirmation design layout meets ERs and planning requirements under the EPC contract. | E10: Ethical Power | F10: H | I10: P | J10: IFC drawings to be issued | K10: Each IFC drawing
A11: 2 | B11: M | C11: Material review | D11: Inspection and confirmation that materials meet the design specification. - Reinforcement bars - Waterstop materials - Set in materials (pipework, ducting) - Earthing materials - Chambers | E11: Contractor | F11: W | I11: P EP-1528-STS-FS-1 | J11: Material datasheets Material safety datasheets (if applicable) Material grading certificates | K11: All procured material
A12: 3 | B12: M | C12: Material delivery inspection | D12: Confirmation that delivered material conforms to the design specification and the supplied documentation. - Reinforcement bars - Waterstop materials - Set in materials (pipework, ducting) - Earthing materials - Chambers | E12: Contractor | F12: W | I12: P,V | J12: EP-ITD-00-01 Material delivery | K12: Each delivery of material
A13: 4 | B13: C | C13: Setting out | D13: Inspection and confirmation of setting out activities | E13: Contractor | F13: W | I13: P,DI | J13: EP-ITD-01-01 Setting out | K13: Each foundation
A14: 5 | B14: C | C14: Excavation | D14: Confirmation of excavation condition and preparation | E14: Contractor | F14: W | I14: V,DI | J14: EP-ITD-01-07 Excavation/Earthworks | K14: 1 inspection for each excavation
A15: 6 | B15: C | C15: Final CCTV Base inspection | E15: Contractor | F15: W | I15: V,DI | J15: EP-ITD-14-01 CCTV Pole inspection | K15: Each concrete pour
A16: 7 | B16: C | C16: Redline & As-Built records | D16: Handover of all redline marked up drawins to be added to as-built designs | E16: Contractor | F16: H | I16: P | J16: RL drawings | K16: Each design

Sheet 07 Inverter and Isolator
A3: Inspection and Test Plan | J3: Witness (W) - Opporunity shall be given to the required representatives to witness the works. Works can commence if no representative is present at the informed time Hold (H) - Works shall not proceed until works are witnessed by the required representatives Surveillance (S) - Works commence and will be witnessed on an ad-hoc basis
A4: Project Name | D4: =Introduction!D3 -> Hessay | F4: Project Number | I4: =Introduction!K3 -> EC006
A5: ITP Scope | D5: =Introduction!B6 -> SOLAR
A7: Ref | B7: Phase P = Pre works M = Material C = Construction | C7: Element | D7: Inspection/Test Description | E7: Responsibility for Completion | F7: Witness | I7: Standard/Pass Criteria V = Visual DI = Dimension P = As per Project Drawings / Design TPI = Third Party Inspection T= Test | J7: Evidence/Required Documentation | K7: Frequency | L7: Quantity for Project | M7: Post Inspection/Test | P7: file location (hyperlink) | Q7: Uploaded to SharePoint
F8: EPC | G8: Client | H8: DNO | M8: Completed By | N8: Date | O8: Pass/Fail
A9: String Inverter
A10: 1 | B10: M | C10: Material delivery inspection | D10: Visual inspection of material condition on delivery. Confirmation that material spec meets design requirements | E10: Contractor | F10: W | I10: V | J10: EP-ITD-00-01 Material Delivery | K10: Each delivery of material
A11: 2 | B11: C | C11: Inverter mounting installation inspection | D11: Confirmation of Inverter mounitng structure and Inverter condition | E11: Contractor | F11: W | I11: V,DI | J11: EP-ITD-11-01 String Inverter Mounting Inspection | K11: Each inverter (100%)
A12: 3 | B12: C | C12: Inverter termination inspection | D12: Confirmation of Inverter LV AC and DC terminations | E12: Contractor | F12: W | I12: V,DI | J12: EP-ITD-11-02 String Inverter Terminations Inspection | K12: Each inverter (100%)
A13: 4 | B13: C | C13: Redline & As-Built records | D13: Handover of all redline marked up drawins to be added to as-built designs | E13: Contractor | F13: H | I13: P | J13: RL drawings | K13: Each field
A14: LV AC Isolator
A15: 1 | B15: M | C15: Material delivery inspection | D15: Visual inspection of material condition on delivery. Confirmation that material spec meets design requirements | E15: Contractor | F15: W | I15: V | J15: EP-ITD-00-01 Material Delivery | K15: Each delivery of material
A16: 2 | B16: C | C16: LV AC Isolator mounting installation inspection | D16: Confirmation of LV AC Isolator mounitng structure and Inverter condition | E16: Contractor | F16: W | I16: V,DI | J16: EP-ITD-12-01 AC Isolator Mounting Inspection | K16: Each inverter (100%)
A17: 3 | B17: C | C17: LV AC Isolator termination inspection | D17: Confirmation of LV AC terminations | E17: Contractor | F17: W | I17: V,DI | J17: EP-ITD-12-02 AC Isolator Installation Inspection | K17: Each inverter (100%)
A18: 4 | B18: C | C18: Redline & As-Built records | D18: Handover of all redline marked up drawins to be added to as-built designs | E18: Contractor | F18: H | I18: P | J18: RL drawings | K18: Each field

Sheet 06 Mounting Structure
A3: Inspection and Test Plan | J3: Witness (W) - Opporunity shall be given to the required representatives to witness the works. Works can commence if no representative is present at the informed time Hold (H) - Works shall not proceed until works are witnessed by the required representatives Surveillance (S) - Works commence and will be witnessed on an ad-hoc basis
A4: Project Name | D4: =Introduction!D3 -> Hessay | F4: Project Number | I4: =Introduction!K3 -> EC006
A5: ITP Scope | D5: =Introduction!B6 -> SOLAR
A7: Ref | B7: Phase P = Pre works M = Material C = Construction | C7: Element | D7: Inspection/Test Description | E7: Responsibility for Completion | F7: Witness | I7: Standard/Pass Criteria V = Visual DI = Dimension P = As per Project Drawings / Design TPI = Third Party Inspection T= Test | J7: Evidence/Required Documentation | K7: Frequency | L7: Quantity for Project | M7: Post Inspection/Test | P7: file location (hyperlink) | Q7: Uploaded to SharePoint
F8: EPC | G8: Client | H8: DNO | M8: Completed By | N8: Date | O8: Pass/Fail
A9: Piling
A10: 1 | B10: M | C10: Material delivery inspection | D10: Visual inspection of material condition on delivery. Confirmation that material spec meets design requirements | E10: Contractor | F10: W | I10: V | J10: EP-ITD-00-01 Material Delivery | K10: Each delivery of material
A11: 2 | B11: C | C11: Setting out | D11: Confirmation of setting out activities | E11: Contractor | F11: H | I11: V,DI | J11: EP-ITD-01-01 Setting out | K11: 1x per field
A12: 3 | B12: C | C12: Piling installation inspection | D12: Confirmation of pile installation as per manufactuer installation guidance | E12: Contractor | F12: W | I12: V,DI | J12: EP-ITD-10-01 Piling/Footing inspection | K12: Each table (100%)
A13: 4 | B13: C | C13: Redline & As-Built records | D13: Handover of all redline marked up drawins to be added to as-built designs | E13: Contractor | F13: H | I13: P | J13: RL drawings | K13: Each field
A14: Mounting Structure
A15: 1 | B15: M | C15: Material delivery inspection | D15: Visual inspection of material condition on delivery. Confirmation that material spec meets design requirements | E15: Contractor | F15: W | I15: V | J15: EP-ITD-00-01 Material Delivery | K15: Each delivery of material
A16: 2 | B16: C | C16: Setting out | D16: Confirmation of setting out activities | E16: Contractor | F16: H | I16: V,DI | J16: EP-ITD-01-01 Setting out | K16: 1x per field
A17: 3 | B17: C | C17: Mounting Structure installation inspection | D17: Confirmation of Mounting structure installation as per manufactuer installation guidance | E17: Contractor | F17: W | I17: V,DI | J17: EP-ITD-10-02 Mounting Strucutre inspection | K17: Each table (100%)
A18: 4 | B18: C | C18: Redline & As-Built records | D18: Handover of all redline marked up drawins to be added to as-built designs | E18: Contractor | F18: H | I18: P | J18: RL drawings | K18: Each field
A19: PV Module mounting
A20: 1 | B20: M | C20: Material delivery inspection | D20: Visual inspection of material condition on delivery. Confirmation that material spec meets design requirements | E20: Contractor | F20: W | I20: V | J20: EP-ITD-00-01 Material Delivery | K20: Each delivery of material
A21: 2 | B21: C | C21: Setting out | D21: Confirmation of setting out activities | E21: Contractor | F21: H | I21: V,DI | J21: EP-ITD-01-01 Setting out | K21: 1x per field
A22: 3 | B22: C | C22: PV Module installation inspection | D22: Confirmation of PV Module installation as per manufactuer installation guidance | E22: Contractor | F22: W | I22: V,DI | J22: EP-ITD-10-03 PV Module Mounting Inspection | K22: Each table (100%)
A23: 4 | B23: C | C23: Redline & As-Built records | D23: Handover of all redline marked up drawins to be added to as-built designs | E23: Contractor | F23: H | I23: P | J23: RL drawings | K23: Each field

Sheet 08 Meteo and Weather station
A3: Inspection and Test Plan | J3: Witness (W) - Opporunity shall be given to the required representatives to witness the works. Works can commence if no representative is present at the informed time Hold (H) - Works shall not proceed until works are witnessed by the required representatives Surveillance (S) - Works commence and will be witnessed on an ad-hoc basis
A4: Project Name | D4: =Introduction!D3 -> Hessay | F4: Project Number | I4: =Introduction!K3 -> EC006
A5: ITP Scope | D5: =Introduction!B6 -> SOLAR
A7: Ref | B7: Phase P = Pre works M = Material C = Construction | C7: Element | D7: Inspection/Test Description | E7: Responsibility for Completion | F7: Witness | I7: Standard/Pass Criteria V = Visual DI = Dimension P = As per Project Drawings / Design TPI = Third Party Inspection T= Test | J7: Evidence/Required Documentation | K7: Frequency | L7: Quantity for Project | M7: Post Inspection/Test | P7: file location (hyperlink) | Q7: Uploaded to SharePoint
F8: EPC | G8: Client | H8: DNO | M8: Completed By | N8: Date | O8: Pass/Fail
A9: Weather Stations
A10: 1 | B10: M | C10: Material delivery inspection | D10: Visual inspection of material condition on delivery. Confirmation that material spec meets design requirements | E10: Contractor | F10: W | I10: V | J10: EP-ITD-00-01 Material Delivery | K10: Each delivery of material
A11: 2 | B11: C | C11: Setting out | D11: Confirmation of setting out activities | E11: Contractor | F11: H | I11: V,DI | J11: EP-ITD-01-01 Setting out | K11: 1x per field
A12: 3 | B12: C | C12: Wather station mounting installation | D12: Confirmation of Mounting structure installation as per manufactuer installation guidance | E12: Contractor | F12: W | I12: V,DI | J12: EP-ITD-15-01 Meteo Station inspection | K12: Each eather station (100%)
A13: 4 | B13: C | C13: Redline & As-Built records | D13: Handover of all redline marked up drawins to be added to as-built designs | E13: Contractor | F13: H | I13: P | J13: RL drawings | K13: Each field

Sheet 09 Transformer Station
A3: Inspection and Test Plan | J3: Witness (W) - Opporunity shall be given to the required representatives to witness the works. Works can commence if no representative is present at the informed time Hold (H) - Works shall not proceed until works are witnessed by the required representatives Surveillance (S) - Works commence and will be witnessed on an ad-hoc basis
A4: Project Name | F4: Project Number
A5: ITP Scope
A7: Ref | B7: Phase P = Pre works M = Material C = Construction | C7: Element | D7: Inspection/Test Description | E7: Responsibility for Completion | F7: Witness | I7: Standard/Pass Criteria V = Visual DI = Dimension P = As per Project Drawings / Design TPI = Third Party Inspection T= Test | J7: Evidence/Required Documentation | K7: Frequency | L7: Quantity for Project | M7: Post Inspection/Test | P7: file location (hyperlink) | Q7: Uploaded to SharePoint
F8: EPC | G8: Client | H8: DNO | M8: Completed By | N8: Date | O8: Pass/Fail
A9: Transformer station housing
A10: 1 | B10: M | C10: Transformer station inspection on delivery | D10: Visual inspection of the transformer station prior to landing and any installation works. | E10: Contractor | F10: W | I10: V | J10: EP-ITD-00-01 Material Delivery | K10: Every transformer station
A11: 2 | B11: C | C11: Transformer station inspection on completion of installation | D11: Visual inspection of the transformer station after installation works have been completed and prior to energisation. | E11: Contractor, EP | F11: H | G11: W | I11: V | J11: EP-ITD-07-06 MV Station inspection | K11: Every transformer station
A12: 3 | B12: C | C12: Redline & As-Built records | D12: Handover of all redline marked up drawins to be added to as-built designs | E12: Contractor | F12: H | I12: P | J12: RL drawings | K12: Every transformer station
A13: HV Switchgear
A14: 1 | B14: C | C14: HV Cable terminations inspection | D14: Inspection of HV terminations within each switchgear cabinet. | E14: Contractor | F14: H | I14: V | J14: EP-ITD-08-09 HV Cable termination to RMU or Switchgear | K14: Every switchgear cabinet
A15: 2 | B15: C | C15: Switchgear pre-energisation inspection | D15: Complete inspection of the switchgear and HV terminations prior to energisation. | E15: Contractor, EP | F15: H | G15: W | I15: V | J15: EP-07-07 Switchgear Inspection | K15: Every switchgear cabinet
A16: LV Pillar
A17: 1 | B17: C | C17: LV Pillar pre-energisation inspection | D17: Complete inspection of the LV Pillar terminations and components prior to energisation. | E17: Contractor, EP | F17: H | G17: W | I17: V | J17: EP-07-08 LV Pillar inspection | K17: Every LV Pillar

Sheet TEMPLATE
A3: Inspection and Test Plan | J3: Witness (W) - Opporunity shall be given to the required representatives to witness the works. Works can commence if no representative is present at the informed time Hold (H) - Works shall not proceed until works are witnessed by the required representatives Surveillance (S) - Works commence and will be witnessed on an ad-hoc basis
A4: Project Name | F4: Project Number
A5: ITP Scope
A7: Ref | B7: Phase P = Pre works M = Material C = Construction | C7: Element | D7: Inspection/Test Description | E7: Responsibility for Completion | F7: Witness | I7: Standard/Pass Criteria V = Visual DI = Dimension P = As per Project Drawings / Design TPI = Third Party Inspection T= Test | J7: Evidence/Required Documentation | K7: Frequency | L7: Quantity for Project | M7: Post Inspection/Test | P7: file location (hyperlink) | Q7: Uploaded to SharePoint
F8: EPC | G8: Client | H8: DNO | M8: Completed By | N8: Date | O8: Pass/Fail
