Workbook

Sheet Summary
A1: Jobs Tracker — summary against the investor deck
A2: Model figures are formulas from the option sheets; 'Deck' columns are the rounded figures printed on slides 14–16 (hardcoded for comparison).
A4: OPTION A — £500k: referrals + one trades salesperson
B5: M4 | C5: M6 | D5: M9 | E5: M12 | F5: Year 1 | G5: Year 2 | H5: Year 3
A6: New firms signed in month / average per month in year | B6: ='Option A'!E8 -> 2 | C6: ='Option A'!G8 -> 4 | D6: ='Option A'!J8 -> 6 | E6: ='Option A'!M8 -> 9 | F6: =AVERAGE('Option A'!B8:M8) -> 4.0833333 | G6: =AVERAGE('Option A'!N8:Y8) -> 12 | H6: =AVERAGE('Option A'!Z8:AK8) -> 18
A7: Firms on the platform at end | B7: ='Option A'!E10 -> 3.921192 | C7: ='Option A'!G10 -> 10.81316 | D7: ='Option A'!J10 -> 26.342499 | E7: ='Option A'!M10 -> 49.3408 | F7: ='Option A'!M10 -> 49.3408 | G7: ='Option A'!Y10 -> 180.76756 | H7: ='Option A'!AK10 -> 365.43134
A8: Total MRR at end, £ | B8: ='Option A'!E14 -> 5376.8182 | C8: ='Option A'!G14 -> 13525.785 | D8: ='Option A'!J14 -> 31898.972 | E8: ='Option A'!M14 -> 59786.052 | F8: ='Option A'!M14 -> 59786.052 | G8: ='Option A'!Y14 -> 231944.87 | H8: ='Option A'!AK14 -> 489008.21
A9: ARR run-rate at end, £ | B9: ='Option A'!E15 -> 64521.819 | C9: ='Option A'!G15 -> 162309.41 | D9: ='Option A'!J15 -> 382787.67 | E9: ='Option A'!M15 -> 717432.63 | F9: ='Option A'!M15 -> 717432.63 | G9: ='Option A'!Y15 -> 2783338.5 | H9: ='Option A'!AK15 -> 5868098.5
A10: Set-up fees in year, £ | F10: =SUM('Option A'!B17:M17) -> 196000 | G10: =SUM('Option A'!N17:Y17) -> 576000 | H10: =SUM('Option A'!Z17:AK17) -> 864000
A11: Revenue in year incl. set-up, £ | F11: =SUM('Option A'!B18:M18) -> 459199.63 | G11: =SUM('Option A'!N18:Y18) -> 2374313.8 | H11: =SUM('Option A'!Z18:AK18) -> 5340252.8
A12: Costs in year, £ | F12: =SUM('Option A'!B28:M28) -> 392430.55 | G12: =SUM('Option A'!N28:Y28) -> 854216.68 | H12: =SUM('Option A'!Z28:AK28) -> 1190731.5
A13: Cash at end, £ | B13: ='Option A'!E32 -> 435250.46 | C13: ='Option A'!G32 -> 414319.46 | D13: ='Option A'!J32 -> 441570.04 | E13: ='Option A'!M32 -> 566769.08 | F13: ='Option A'!M32 -> 566769.08 | G13: ='Option A'!Y32 -> 2086866.2 | H13: ='Option A'!AK32 -> 6236387.5
A14: Lowest cash balance in 36 months, £ / month | B14: =MIN('Option A'!B32:AK32) -> 414319.46 | C14: =MATCH(B14,'Option A'!B32:AK32,0) -> 6 | D14: ← month index; negative means a seed round is needed before that month
A15: Months of runway on this round alone (first month cash < 0) | B15: =IFERROR(MATCH(TRUE(),INDEX('Option A'!B32:AK32<0,0),0)-1,">36") -> >36
A17: Deck (slides 14–16) shows: | B17: M4 | C17: M6 | D17: M9 | E17: M12 | F17: Year 1 | G17: Year 2 | H17: Year 3
A18: Firms on the platform | B18: 4 | C18: 11 | D18: 27 | E18: 51 | F18: 50 | G18: 180 | H18: 364
A19: MRR, £ | B19: 5000 | C19: 13000 | D19: 32000 | E19: 60000
A20: ARR run-rate, £ | F20: 700000 | G20: 2800000 | H20: 6000000
A21: Set-up fees in year, £ | F21: 195000
A22: Revenue in year, £ | F22: 500000 | G22: 2500000 | H22: 5500000
A24: OPTION B — £1m: plus national marketing and an onboarding hire
B25: M4 | C25: M6 | D25: M9 | E25: M12 | F25: Year 1 | G25: Year 2 | H25: Year 3
A26: New firms signed in month / average per month in year | B26: ='Option B'!E8 -> 3 | C26: ='Option B'!G8 -> 7 | D26: ='Option B'!J8 -> 11 | E26: ='Option B'!M8 -> 16 | F26: =AVERAGE('Option B'!B8:M8) -> 7.1666667 | G26: =AVERAGE('Option B'!N8:Y8) -> 24.166667 | H26: =AVERAGE('Option B'!Z8:AK8) -> 36.5
A27: Firms on the platform at end | B27: ='Option B'!E10 -> 4.921192 | C27: ='Option B'!G10 -> 16.77326 | D27: ='Option B'!J10 -> 44.025878 | E27: ='Option B'!M10 -> 85.319565 | F27: ='Option B'!M10 -> 85.319565 | G27: ='Option B'!Y10 -> 351.73486 | H27: ='Option B'!AK10 -> 727.82807
A28: Total MRR at end, £ | B28: ='Option B'!E14 -> 6561.3182 | C28: ='Option B'!G14 -> 20585.523 | D28: ='Option B'!J14 -> 52844.935 | E28: ='Option B'!M14 -> 102402.9 | F28: ='Option B'!M14 -> 102402.9 | G28: ='Option B'!Y14 -> 449700.59 | H28: ='Option B'!AK14 -> 972036.24
A29: ARR run-rate at end, £ | B29: ='Option B'!E15 -> 78735.819 | C29: ='Option B'!G15 -> 247026.28 | D29: ='Option B'!J15 -> 634139.22 | E29: ='Option B'!M15 -> 1228834.8 | F29: ='Option B'!M15 -> 1228834.8 | G29: ='Option B'!Y15 -> 5396407 | H29: ='Option B'!AK15 -> 11664435
A30: Set-up fees in year, £ | F30: =SUM('Option B'!B17:M17) -> 344000 | G30: =SUM('Option B'!N17:Y17) -> 1160000 | H30: =SUM('Option B'!Z17:AK17) -> 1752000
A31: Revenue in year incl. set-up, £ | F31: =SUM('Option B'!B18:M18) -> 770781.76 | G31: =SUM('Option B'!N18:Y18) -> 4540832.7 | H31: =SUM('Option B'!Z18:AK18) -> 10587594
A32: Costs in year, £ | F32: =SUM('Option B'!B28:M28) -> 745060.9 | G32: =SUM('Option B'!N28:Y28) -> 1377995.4 | H32: =SUM('Option B'!Z28:AK28) -> 2057004.2
A33: Cash at end, £ | B33: ='Option B'!E32 -> 871768.3 | C33: ='Option B'!G32 -> 818601.09 | D33: ='Option B'!J32 -> 835939.67 | E33: ='Option B'!M32 -> 1025720.9 | F33: ='Option B'!M32 -> 1025720.9 | G33: ='Option B'!Y32 -> 4188558.1 | H33: ='Option B'!AK32 -> 12719148
A34: Lowest cash balance in 36 months, £ / month | B34: =MIN('Option B'!B32:AK32) -> 812972.54 | C34: =MATCH(B34,'Option B'!B32:AK32,0) -> 7 | D34: ← month index; negative means a seed round is needed before that month
A35: Months of runway on this round alone (first month cash < 0) | B35: =IFERROR(MATCH(TRUE(),INDEX('Option B'!B32:AK32<0,0),0)-1,">36") -> >36
A37: Deck (slides 14–16) shows: | B37: M4 | C37: M6 | D37: M9 | E37: M12 | F37: Year 1 | G37: Year 2 | H37: Year 3
A38: Firms on the platform | B38: 5 | C38: 17 | D38: 45 | E38: 88 | F38: 85 | G38: 348 | H38: 718
A39: MRR, £ | B39: 7000 | C39: 20000 | D39: 53000 | E39: 100000
A40: ARR run-rate, £ | F40: 1200000 | G40: 5400000 | H40: 11800000
A41: Set-up fees in year, £ | F41: 345000
A42: Revenue in year, £ | F42: 800000 | G42: 4700000 | H42: 10700000
A44: Targets, not forecasts: there is no repeatable sales channel yet. Change the new-firms rows on the Assumptions sheet to test other ramps.

Sheet Assumptions
A1: Jobs Tracker — 36-month financial model
A2: Blue cells with yellow fill are inputs; everything else is a formula. Month 1 = November 2026 (Gaswise billing starts). Figures in £, excluding VAT.
A4: COMMERCIAL
A5: Model start (month 1) | B5: 46327 | D5: Gaswise billing and set-up fee start 1 November 2026
A6: Average new contract, £ per month at list | B6: 1150 | D6: Franck: target mix of 15–30, 30–50 and 50+ worker firms at £30/worker + £50/admin; CBES-sized firm is £1,100
A7: Set-up fee per new firm, £ one-off | B7: 4000 | D7: Rate card, October 2026; every new firm pays it
A8: Monthly logo churn | B8: 0.01 | D8: Assumption: ~11% annual; no data yet (product live 3 months)
A9: Price uplift at each annual renewal | B9: 0.03 | D9: Applied to the whole subscription base at months 13 and 25
A10: Existing MRR at month 0 (CBES net £440 + Gaswise £2,600), £ | B10: 3040 | D10: CBES £1,100 list less 60% first-year pilot discount; Gaswise £2,600 at list
A11: CBES discount ends: month | B11: 10 | D11: Initial term 1 Aug 2026 – 31 Jul 2027; list price from August 2027 = month 10
A12: CBES MRR step-up when discount ends, £ | B12: 660 | D12: £1,100 − £440
A13: Existing firms at month 0 | B13: 2 | D13: CBES and Gaswise
A14: Sales achievement vs plan (sensitivity) | B14: 1 | D14: 1 = the ramp as printed on the deck; 0.5 = half the new firms each month. Use it to see when cash runs out if sales come slower
A15: ADD-ONS (storage packs, SMS credits, AI quote-writing)
A16: Add-ons as share of subscription MRR, year 1 | B16: 0.03 | D16: Adoption ~30% of firms in year 1; AI at £5 per field worker, storage £20 per 50 GB
A17: Add-ons as share of subscription MRR, year 2 | B17: 0.1
A18: Add-ons as share of subscription MRR, year 3 | B18: 0.14 | D18: Adoption ~60% by year 3
A19: HOSTING
A20: Azure hosting, £ per firm per month | B20: 40 | D20: Franck: ~£2,000/month for ~50 organisations; multi-tenant, scales roughly linearly
A21: Azure hosting floor, £ per month | B21: 500 | D21: Fixed cost of the environment at low customer counts
A22: ROUND
A23: Round received in month | B23: 1 | D23: Model assumes close at month 1; shift to test a later close
A24: Option A round, £ | B24: 500000 | D24: Deck slide 16
A25: Option B round, £ | B25: 1000000 | D25: Deck slide 16
A26: TEAM AND SPEND — Option A (£ per year unless stated)
A27: Two developers, cost per year (both) | B27: 160000 | D27: £200k over 15 months on the deck
A28: Developers start month | B28: 3 | D28: Within 60 days of close
A29: Sales hire start month | B29: 2
A30: Integrations budget (Sage API, telematics, stores), £ total | B30: 50000 | D30: Spread evenly over months 3–12
A31: Marketing, cost per year — Option A | B31: 40000 | D31: £50k over 15 months: CampaignBuilder outbound, trade bodies, events
A32: Marketing, cost per year — Option B | B32: 360000 | D32: £450k over 15 months: adds national paid search, content, events
A33: Marketing start month | B33: 3
A34: Onboarding / customer-success hire, cost per year — Option B only | B34: 40000 | D34: £50k over 15 months; starts month 4
A35: Onboarding hire start month (B) | B35: 4
A36: Legal, finance, contingency, £ per month — Option A | B36: 2500 | D36: £60k over 15 months less hosting (modelled separately)
A37: Legal, finance, contingency, £ per month — Option B | B37: 5500 | D37: £110k over 15 months less hosting
A38: Founder salary, £ per year | B38: 48000 | D38: Franck: £4,000 a month from close; £60k over the 15-month budget on deck slide 16
A39: SCALING WITH VOLUME (drives years 2–3; the deck says a seed round in year 2 funds them)
A40: New firms closed per salesperson per month, at full ramp | B40: 8 | D40: Franck's own target for the first hire is 8–9 a month; extra salespeople are added when the ramp needs them
A41: Salesperson cost per year, each | B41: 64000 | D41: Same basis as the first hire
...

Sheet Option A
A1: Option A — monthly model, 36 months
A2: All cells are formulas driven by the Assumptions sheet. £ excluding VAT.
A4: Month | B4: 1 | C4: 2 | D4: 3 | E4: 4 | F4: 5 | G4: 6 | H4: 7 | I4: 8 | J4: 9 | K4: 10 | L4: 11 | M4: 12 | N4: 13 | O4: 14 | P4: 15 | Q4: 16 | R4: 17 | S4: 18 | T4: 19 | U4: 20 | V4: 21 | W4: 22 | X4: 23 | Y4: 24 | Z4: 25 | AA4: 26 | AB4: 27 | AC4: 28 | AD4: 29 | AE4: 30 | AF4: 31 | AG4: 32 | AH4: 33 | AI4: 34 | AJ4: 35 | AK4: 36
A5: Calendar month | B5: =EDATE(Assumptions!$B$5,B4-1) -> 46327 | C5: =EDATE(Assumptions!$B$5,C4-1) -> 46357 | D5: =EDATE(Assumptions!$B$5,D4-1) -> 46388 | E5: =EDATE(Assumptions!$B$5,E4-1) -> 46419 | F5: =EDATE(Assumptions!$B$5,F4-1) -> 46447 | G5: =EDATE(Assumptions!$B$5,G4-1) -> 46478 | H5: =EDATE(Assumptions!$B$5,H4-1) -> 46508 | I5: =EDATE(Assumptions!$B$5,I4-1) -> 46539 | ... AK5: =EDATE(Assumptions!$B$5,AK4-1) -> 47392
A6: CUSTOMERS
A7: Firms at start of month | B7: =Assumptions!$B$13 -> 2 | C7: =B10 -> 1.98 | D7: =C10 -> 1.9602 | E7: =D10 -> 1.940598 | F7: =E10 -> 3.921192 | G7: =F10 -> 6.8819801 | H7: =G10 -> 10.81316 | I7: =H10 -> 15.705029 | J7: =I10 -> 20.547978 | ... AK7: =AJ10 -> 347.91044
A8: New firms signed | B8: =ROUND(Assumptions!C52*Assumptions!$B$14,0) -> 0 | C8: =ROUND(Assumptions!D52*Assumptions!$B$14,0) -> 0 | D8: =ROUND(Assumptions!E52*Assumptions!$B$14,0) -> 0 | E8: =ROUND(Assumptions!F52*Assumptions!$B$14,0) -> 2 | F8: =ROUND(Assumptions!G52*Assumptions!$B$14,0) -> 3 | G8: =ROUND(Assumptions!H52*Assumptions!$B$14,0) -> 4 | H8: =ROUND(Assumptions!I52*Assumptions!$B$14,0) -> 5 | I8: =ROUND(Assumptions!J52*Assumptions!$B$14,0) -> 5 | ... AK8: =ROUND(Assumptions!AL52*Assumptions!$B$14,0) -> 21
A9: Firms churned | B9: =B7*Assumptions!$B$8 -> 0.02 | C9: =C7*Assumptions!$B$8 -> 0.0198 | D9: =D7*Assumptions!$B$8 -> 0.019602 | E9: =E7*Assumptions!$B$8 -> 0.01940598 | F9: =F7*Assumptions!$B$8 -> 0.03921192 | G9: =G7*Assumptions!$B$8 -> 0.068819801 | H9: =H7*Assumptions!$B$8 -> 0.1081316 | I9: =I7*Assumptions!$B$8 -> 0.15705029 | ... AK9: =AK7*Assumptions!$B$8 -> 3.4791044
A10: Firms at end of month | B10: =B7-B9+B8 -> 1.98 | C10: =C7-C9+C8 -> 1.9602 | D10: =D7-D9+D8 -> 1.940598 | E10: =E7-E9+E8 -> 3.921192 | F10: =F7-F9+F8 -> 6.8819801 | G10: =G7-G9+G8 -> 10.81316 | H10: =H7-H9+H8 -> 15.705029 | I10: =I7-I9+I8 -> 20.547978 | ... AK10: =AK7-AK9+AK8 -> 365.43134
A11: RECURRING REVENUE
A12: Subscription MRR, £ | B12: =(Assumptions!$B$10*(1-Assumptions!$B$8)+B8*Assumptions!$B$6+IF(B4=Assumptions!$B$11,Assumptions!$B$12,0))*IF(OR(B4=13,B4=25),1+Assumptions!$B$9,1) -> 3009.6 | C12: =(B12*(1-Assumptions!$B$8)+C8*Assumptions!$B$6+IF(C4=Assumptions!$B$11,Assumptions!$B$12,0))*IF(OR(C4=13,C4=25),1+Assumptions!$B$9,1) -> 2979.504 | D12: =(C12*(1-Assumptions!$B$8)+D8*Assumptions!$B$6+IF(D4=Assumptions!$B$11,Assumptions!$B$12,0))*IF(OR(D4=13,D4=25),1+Assumptions!$B$9,1) -> 2949.709 | E12: =(D12*(1-Assumptions!$B$8)+E8*Assumptions!$B$6+IF(E4=Assumptions!$B$11,Assumptions!$B$12,0))*IF(OR(E4=13,E4=25),1+Assumptions!$B$9,1) -> 5220.2119 | F12: =(E12*(1-Assumptions!$B$8)+F8*Assumptions!$B$6+IF(F4=Assumptions!$B$11,Assumptions!$B$12,0))*IF(OR(F4=13,F4=25),1+Assumptions!$B$9,1) -> 8618.0098 | G12: =(F12*(1-Assumptions!$B$8)+G8*Assumptions!$B$6+IF(G4=Assumptions!$B$11,Assumptions!$B$12,0))*IF(OR(G4=13,G4=25),1+Assumptions!$B$9,1) -> 13131.83 | H12: =(G12*(1-Assumptions!$B$8)+H8*Assumptions!$B$6+IF(H4=Assumptions!$B$11,Assumptions!$B$12,0))*IF(OR(H4=13,H4=25),1+Assumptions!$B$9,1) -> 18750.511 | I12: =(H12*(1-Assumptions!$B$8)+I8*Assumptions!$B$6+IF(I4=Assumptions!$B$11,Assumptions!$B$12,0))*IF(OR(I4=13,I4=25),1+Assumptions!$B$9,1) -> 24313.006 | J12: =(I12*(1-Assumptions!$B$8)+J8*Assumptions!$B$6+IF(J4=Assumptions!$B$11,Assumptions!$B$12,0))*IF(OR(J4=13,J4=25),1+Assumptions!$B$9,1) -> 30969.876 | ... AK12: =(AJ12*(1-Assumptions!$B$8)+AK8*Assumptions!$B$6+IF(AK4=Assumptions!$B$11,Assumptions!$B$12,0))*IF(OR(AK4=13,AK4=25),1+Assumptions!$B$9,1) -> 428954.57
A13: Add-on MRR, £ | B13: =B12*IF(B4<=12,Assumptions!$B$16,IF(B4<=24,Assumptions!$B$17,Assumptions!$B$18)) -> 90.288 | C13: =C12*IF(C4<=12,Assumptions!$B$16,IF(C4<=24,Assumptions!$B$17,Assumptions!$B$18)) -> 89.38512 | D13: =D12*IF(D4<=12,Assumptions!$B$16,IF(D4<=24,Assumptions!$B$17,Assumptions!$B$18)) -> 88.491269 | E13: =E12*IF(E4<=12,Assumptions!$B$16,IF(E4<=24,Assumptions!$B$17,Assumptions!$B$18)) -> 156.60636 | F13: =F12*IF(F4<=12,Assumptions!$B$16,IF(F4<=24,Assumptions!$B$17,Assumptions!$B$18)) -> 258.54029 | G13: =G12*IF(G4<=12,Assumptions!$B$16,IF(G4<=24,Assumptions!$B$17,Assumptions!$B$18)) -> 393.95489 | H13: =H12*IF(H4<=12,Assumptions!$B$16,IF(H4<=24,Assumptions!$B$17,Assumptions!$B$18)) -> 562.51534 | I13: =I12*IF(I4<=12,Assumptions!$B$16,IF(I4<=24,Assumptions!$B$17,Assumptions!$B$18)) -> 729.39019 | ... AK13: =AK12*IF(AK4<=12,Assumptions!$B$16,IF(AK4<=24,Assumptions!$B$17,Assumptions!$B$18)) -> 60053.639
A14: Total MRR, £ | B14: =B12+B13 -> 3099.888 | C14: =C12+C13 -> 3068.8891 | D14: =D12+D13 -> 3038.2002 | E14: =E12+E13 -> 5376.8182 | F14: =F12+F13 -> 8876.55 | G14: =G12+G13 -> 13525.785 | H14: =H12+H13 -> 19313.027 | I14: =I12+I13 -> 25042.396 | ... AK14: =AK12+AK13 -> 489008.21
A15: ARR run-rate (MRR × 12), £ | B15: =B14*12 -> 37198.656 | C15: =C14*12 -> 36826.669 | D15: =D14*12 -> 36458.403 | E15: =E14*12 -> 64521.819 | F15: =F14*12 -> 106518.6 | G15: =G14*12 -> 162309.41 | H15: =H14*12 -> 231756.32 | I15: =I14*12 -> 300508.76 | ... AK15: =AK14*12 -> 5868098.5
A16: ONE-OFF
A17: Set-up fees, £ | B17: =B8*Assumptions!$B$7 -> 0 | C17: =C8*Assumptions!$B$7 -> 0 | D17: =D8*Assumptions!$B$7 -> 0 | E17: =E8*Assumptions!$B$7 -> 8000 | F17: =F8*Assumptions!$B$7 -> 12000 | G17: =G8*Assumptions!$B$7 -> 16000 | H17: =H8*Assumptions!$B$7 -> 20000 | I17: =I8*Assumptions!$B$7 -> 20000 | ... AK17: =AK8*Assumptions!$B$7 -> 84000
A18: Total revenue in month, £ | B18: =B14+B17 -> 3099.888 | C18: =C14+C17 -> 3068.8891 | D18: =D14+D17 -> 3038.2002 | E18: =E14+E17 -> 13376.818 | F18: =F14+F17 -> 20876.55 | G18: =G14+G17 -> 29525.785 | H18: =H14+H17 -> 39313.027 | I18: =I14+I17 -> 45042.396 | ... AK18: =AK14+AK17 -> 573008.21
A19: COSTS
A20: Developers | B20: =IF(B4>=Assumptions!$B$28,Assumptions!$B$27/12,0)+IF(B4>=13,Assumptions!$B$47/12,0) -> 0 | C20: =IF(C4>=Assumptions!$B$28,Assumptions!$B$27/12,0)+IF(C4>=13,Assumptions!$B$47/12,0) -> 0 | D20: =IF(D4>=Assumptions!$B$28,Assumptions!$B$27/12,0)+IF(D4>=13,Assumptions!$B$47/12,0) -> 13333.333 | E20: =IF(E4>=Assumptions!$B$28,Assumptions!$B$27/12,0)+IF(E4>=13,Assumptions!$B$47/12,0) -> 13333.333 | F20: =IF(F4>=Assumptions!$B$28,Assumptions!$B$27/12,0)+IF(F4>=13,Assumptions!$B$47/12,0) -> 13333.333 | G20: =IF(G4>=Assumptions!$B$28,Assumptions!$B$27/12,0)+IF(G4>=13,Assumptions!$B$47/12,0) -> 13333.333 | H20: =IF(H4>=Assumptions!$B$28,Assumptions!$B$27/12,0)+IF(H4>=13,Assumptions!$B$47/12,0) -> 13333.333 | I20: =IF(I4>=Assumptions!$B$28,Assumptions!$B$27/12,0)+IF(I4>=13,Assumptions!$B$47/12,0) -> 13333.333 | ... AK20: =IF(AK4>=Assumptions!$B$28,Assumptions!$B$27/12,0)+IF(AK4>=13,Assumptions!$B$47/12,0) -> 20000
A21: Sales (headcount scales with new firms) | B21: =IF(B4>=Assumptions!$B$29,MAX(1,ROUNDUP(B8/Assumptions!$B$40,0)),0)*Assumptions!$B$41/12 -> 0 | C21: =IF(C4>=Assumptions!$B$29,MAX(1,ROUNDUP(C8/Assumptions!$B$40,0)),0)*Assumptions!$B$41/12 -> 5333.3333 | D21: =IF(D4>=Assumptions!$B$29,MAX(1,ROUNDUP(D8/Assumptions!$B$40,0)),0)*Assumptions!$B$41/12 -> 5333.3333 | E21: =IF(E4>=Assumptions!$B$29,MAX(1,ROUNDUP(E8/Assumptions!$B$40,0)),0)*Assumptions!$B$41/12 -> 5333.3333 | F21: =IF(F4>=Assumptions!$B$29,MAX(1,ROUNDUP(F8/Assumptions!$B$40,0)),0)*Assumptions!$B$41/12 -> 5333.3333 | G21: =IF(G4>=Assumptions!$B$29,MAX(1,ROUNDUP(G8/Assumptions!$B$40,0)),0)*Assumptions!$B$41/12 -> 5333.3333 | H21: =IF(H4>=Assumptions!$B$29,MAX(1,ROUNDUP(H8/Assumptions!$B$40,0)),0)*Assumptions!$B$41/12 -> 5333.3333 | I21: =IF(I4>=Assumptions!$B$29,MAX(1,ROUNDUP(I8/Assumptions!$B$40,0)),0)*Assumptions!$B$41/12 -> 5333.3333 | ... AK21: =IF(AK4>=Assumptions!$B$29,MAX(1,ROUNDUP(AK8/Assumptions!$B$40,0)),0)*Assumptions!$B$41/12 -> 16000
A22: Integrations | B22: =IF(AND(B4>=3,B4<=12),Assumptions!$B$30/10,0) -> 0 | C22: =IF(AND(C4>=3,C4<=12),Assumptions!$B$30/10,0) -> 0 | D22: =IF(AND(D4>=3,D4<=12),Assumptions!$B$30/10,0) -> 5000 | E22: =IF(AND(E4>=3,E4<=12),Assumptions!$B$30/10,0) -> 5000 | F22: =IF(AND(F4>=3,F4<=12),Assumptions!$B$30/10,0) -> 5000 | G22: =IF(AND(G4>=3,G4<=12),Assumptions!$B$30/10,0) -> 5000 | H22: =IF(AND(H4>=3,H4<=12),Assumptions!$B$30/10,0) -> 5000 | I22: =IF(AND(I4>=3,I4<=12),Assumptions!$B$30/10,0) -> 5000 | ... AK22: =IF(AND(AK4>=3,AK4<=12),Assumptions!$B$30/10,0) -> 0
A23: Marketing | B23: =IF(B4<=12,IF(B4>=Assumptions!$B$33,Assumptions!$B$31/12,0),B8*Assumptions!$B$48) -> 0 | C23: =IF(C4<=12,IF(C4>=Assumptions!$B$33,Assumptions!$B$31/12,0),C8*Assumptions!$B$48) -> 0 | D23: =IF(D4<=12,IF(D4>=Assumptions!$B$33,Assumptions!$B$31/12,0),D8*Assumptions!$B$48) -> 3333.3333 | E23: =IF(E4<=12,IF(E4>=Assumptions!$B$33,Assumptions!$B$31/12,0),E8*Assumptions!$B$48) -> 3333.3333 | F23: =IF(F4<=12,IF(F4>=Assumptions!$B$33,Assumptions!$B$31/12,0),F8*Assumptions!$B$48) -> 3333.3333 | G23: =IF(G4<=12,IF(G4>=Assumptions!$B$33,Assumptions!$B$31/12,0),G8*Assumptions!$B$48) -> 3333.3333 | H23: =IF(H4<=12,IF(H4>=Assumptions!$B$33,Assumptions!$B$31/12,0),H8*Assumptions!$B$48) -> 3333.3333 | I23: =IF(I4<=12,IF(I4>=Assumptions!$B$33,Assumptions!$B$31/12,0),I8*Assumptions!$B$48) -> 3333.3333 | ... AK23: =IF(AK4<=12,IF(AK4>=Assumptions!$B$33,Assumptions!$B$31/12,0),AK8*Assumptions!$B$48) -> 31500
A24: Onboarding and support (scales with volume) | B24: =0+IF(B4>=Assumptions!$B$35,MAX(0,ROUNDUP(MAX(0,B8-Assumptions!$B$43)/Assumptions!$B$42,0)-0),0)*Assumptions!$B$44/12+IF(B4>=13,ROUNDUP(B7/Assumptions!$B$45,0)*Assumptions!$B$46/12,0) -> 0 | C24: =0+IF(C4>=Assumptions!$B$35,MAX(0,ROUNDUP(MAX(0,C8-Assumptions!$B$43)/Assumptions!$B$42,0)-0),0)*Assumptions!$B$44/12+IF(C4>=13,ROUNDUP(C7/Assumptions!$B$45,0)*Assumptions!$B$46/12,0) -> 0 | D24: =0+IF(D4>=Assumptions!$B$35,MAX(0,ROUNDUP(MAX(0,D8-Assumptions!$B$43)/Assumptions!$B$42,0)-0),0)*Assumptions!$B$44/12+IF(D4>=13,ROUNDUP(D7/Assumptions!$B$45,0)*Assumptions!$B$46/12,0) -> 0 | E24: =0+IF(E4>=Assumptions!$B$35,MAX(0,ROUNDUP(MAX(0,E8-Assumptions!$B$43)/Assumptions!$B$42,0)-0),0)*Assumptions!$B$44/12+IF(E4>=13,ROUNDUP(E7/Assumptions!$B$45,0)*Assumptions!$B$46/12,0) -> 0 | F24: =0+IF(F4>=Assumptions!$B$35,MAX(0,ROUNDUP(MAX(0,F8-Assumptions!$B$43)/Assumptions!$B$42,0)-0),0)*Assumptions!$B$44/12+IF(F4>=13,ROUNDUP(F7/Assumptions!$B$45,0)*Assumptions!$B$46/12,0) -> 0 | G24: =0+IF(G4>=Assumptions!$B$35,MAX(0,ROUNDUP(MAX(0,G8-Assumptions!$B$43)/Assumptions!$B$42,0)-0),0)*Assumptions!$B$44/12+IF(G4>=13,ROUNDUP(G7/Assumptions!$B$45,0)*Assumptions!$B$46/12,0) -> 3333.3333 | H24: =0+IF(H4>=Assumptions!$B$35,MAX(0,ROUNDUP(MAX(0,H8-Assumptions!$B$43)/Assumptions!$B$42,0)-0),0)*Assumptions!$B$44/12+IF(H4>=13,ROUNDUP(H7/Assumptions!$B$45,0)*Assumptions!$B$46/12,0) -> 3333.3333 | I24: =0+IF(I4>=Assumptions!$B$35,MAX(0,ROUNDUP(MAX(0,I8-Assumptions!$B$43)/Assumptions!$B$42,0)-0),0)*Assumptions!$B$44/12+IF(I4>=13,ROUNDUP(I7/Assumptions!$B$45,0)*Assumptions!$B$46/12,0) -> 3333.3333 | ... AK24: =0+IF(AK4>=Assumptions!$B$35,MAX(0,ROUNDUP(MAX(0,AK8-Assumptions!$B$43)/Assumptions!$B$42,0)-0),0)*Assumptions!$B$44/12+IF(AK4>=13,ROUNDUP(AK7/Assumptions!$B$45,0)*Assumptions!$B$46/12,0) -> 23333.333
A25: Azure hosting | B25: =MAX(Assumptions!$B$21,B10*Assumptions!$B$20) -> 500 | C25: =MAX(Assumptions!$B$21,C10*Assumptions!$B$20) -> 500 | D25: =MAX(Assumptions!$B$21,D10*Assumptions!$B$20) -> 500 | E25: =MAX(Assumptions!$B$21,E10*Assumptions!$B$20) -> 500 | F25: =MAX(Assumptions!$B$21,F10*Assumptions!$B$20) -> 500 | G25: =MAX(Assumptions!$B$21,G10*Assumptions!$B$20) -> 500 | H25: =MAX(Assumptions!$B$21,H10*Assumptions!$B$20) -> 628.20115 | I25: =MAX(Assumptions!$B$21,I10*Assumptions!$B$20) -> 821.91914 | ... AK25: =MAX(Assumptions!$B$21,AK10*Assumptions!$B$20) -> 14617.253
A26: Legal, finance, contingency | B26: =Assumptions!$B$36 -> 2500 | C26: =Assumptions!$B$36 -> 2500 | D26: =Assumptions!$B$36 -> 2500 | E26: =Assumptions!$B$36 -> 2500 | F26: =Assumptions!$B$36 -> 2500 | G26: =Assumptions!$B$36 -> 2500 | H26: =Assumptions!$B$36 -> 2500 | I26: =Assumptions!$B$36 -> 2500 | ... AK26: =Assumptions!$B$36 -> 2500
A27: Founder salary | B27: =Assumptions!$B$38/12 -> 4000 | C27: =Assumptions!$B$38/12 -> 4000 | D27: =Assumptions!$B$38/12 -> 4000 | E27: =Assumptions!$B$38/12 -> 4000 | F27: =Assumptions!$B$38/12 -> 4000 | G27: =Assumptions!$B$38/12 -> 4000 | H27: =Assumptions!$B$38/12 -> 4000 | I27: =Assumptions!$B$38/12 -> 4000 | ... AK27: =Assumptions!$B$38/12 -> 4000
A28: Total costs, £ | B28: =SUM(B20:B27) -> 7000 | C28: =SUM(C20:C27) -> 12333.333 | D28: =SUM(D20:D27) -> 34000 | E28: =SUM(E20:E27) -> 34000 | F28: =SUM(F20:F27) -> 34000 | G28: =SUM(G20:G27) -> 37333.333 | H28: =SUM(H20:H27) -> 37461.534 | I28: =SUM(I20:I27) -> 37655.252 | ... AK28: =SUM(AK20:AK27) -> 111950.59
A29: CASH
A30: Net cash flow in month, £ | B30: =B18-B28 -> -3900.112 | C30: =C18-C28 -> -9264.4442 | D30: =D18-D28 -> -30961.8 | E30: =E18-E28 -> -20623.182 | F30: =F18-F28 -> -13123.45 | G30: =G18-G28 -> -7807.5488 | H30: =H18-H28 -> 1851.4922 | I30: =I18-I28 -> 7387.144 | ... AK30: =AK18-AK28 -> 461057.62
A31: Round received, £ | B31: =IF(B4=Assumptions!$B$23,Assumptions!$B$24,0) -> 500000 | C31: =IF(C4=Assumptions!$B$23,Assumptions!$B$24,0) -> 0 | D31: =IF(D4=Assumptions!$B$23,Assumptions!$B$24,0) -> 0 | E31: =IF(E4=Assumptions!$B$23,Assumptions!$B$24,0) -> 0 | F31: =IF(F4=Assumptions!$B$23,Assumptions!$B$24,0) -> 0 | G31: =IF(G4=Assumptions!$B$23,Assumptions!$B$24,0) -> 0 | H31: =IF(H4=Assumptions!$B$23,Assumptions!$B$24,0) -> 0 | I31: =IF(I4=Assumptions!$B$23,Assumptions!$B$24,0) -> 0 | ... AK31: =IF(AK4=Assumptions!$B$23,Assumptions!$B$24,0) -> 0
A32: Cash balance at end of month, £ | B32: =B30+B31 -> 496099.89 | C32: =B32+C30+C31 -> 486835.44 | D32: =C32+D30+D31 -> 455873.64 | E32: =D32+E30+E31 -> 435250.46 | F32: =E32+F30+F31 -> 422127.01 | G32: =F32+G30+G31 -> 414319.46 | H32: =G32+H30+H31 -> 416170.96 | I32: =H32+I30+I31 -> 423558.1 | J32: =I32+J30+J31 -> 441570.04 | ... AK32: =AJ32+AK30+AK31 -> 6236387.5

Sheet Option B
A1: Option B — monthly model, 36 months
A2: All cells are formulas driven by the Assumptions sheet. £ excluding VAT.
A4: Month | B4: 1 | C4: 2 | D4: 3 | E4: 4 | F4: 5 | G4: 6 | H4: 7 | I4: 8 | J4: 9 | K4: 10 | L4: 11 | M4: 12 | N4: 13 | O4: 14 | P4: 15 | Q4: 16 | R4: 17 | S4: 18 | T4: 19 | U4: 20 | V4: 21 | W4: 22 | X4: 23 | Y4: 24 | Z4: 25 | AA4: 26 | AB4: 27 | AC4: 28 | AD4: 29 | AE4: 30 | AF4: 31 | AG4: 32 | AH4: 33 | AI4: 34 | AJ4: 35 | AK4: 36
A5: Calendar month | B5: =EDATE(Assumptions!$B$5,B4-1) -> 46327 | C5: =EDATE(Assumptions!$B$5,C4-1) -> 46357 | D5: =EDATE(Assumptions!$B$5,D4-1) -> 46388 | E5: =EDATE(Assumptions!$B$5,E4-1) -> 46419 | F5: =EDATE(Assumptions!$B$5,F4-1) -> 46447 | G5: =EDATE(Assumptions!$B$5,G4-1) -> 46478 | H5: =EDATE(Assumptions!$B$5,H4-1) -> 46508 | I5: =EDATE(Assumptions!$B$5,I4-1) -> 46539 | ... AK5: =EDATE(Assumptions!$B$5,AK4-1) -> 47392
A6: CUSTOMERS
A7: Firms at start of month | B7: =Assumptions!$B$13 -> 2 | C7: =B10 -> 1.98 | D7: =C10 -> 1.9602 | E7: =D10 -> 1.940598 | F7: =E10 -> 4.921192 | G7: =F10 -> 9.8719801 | H7: =G10 -> 16.77326 | I7: =H10 -> 24.605528 | J7: =I10 -> 33.359472 | ... AK7: =AJ10 -> 692.75563
A8: New firms signed | B8: =ROUND(Assumptions!C53*Assumptions!$B$14,0) -> 0 | C8: =ROUND(Assumptions!D53*Assumptions!$B$14,0) -> 0 | D8: =ROUND(Assumptions!E53*Assumptions!$B$14,0) -> 0 | E8: =ROUND(Assumptions!F53*Assumptions!$B$14,0) -> 3 | F8: =ROUND(Assumptions!G53*Assumptions!$B$14,0) -> 5 | G8: =ROUND(Assumptions!H53*Assumptions!$B$14,0) -> 7 | H8: =ROUND(Assumptions!I53*Assumptions!$B$14,0) -> 8 | I8: =ROUND(Assumptions!J53*Assumptions!$B$14,0) -> 9 | ... AK8: =ROUND(Assumptions!AL53*Assumptions!$B$14,0) -> 42
A9: Firms churned | B9: =B7*Assumptions!$B$8 -> 0.02 | C9: =C7*Assumptions!$B$8 -> 0.0198 | D9: =D7*Assumptions!$B$8 -> 0.019602 | E9: =E7*Assumptions!$B$8 -> 0.01940598 | F9: =F7*Assumptions!$B$8 -> 0.04921192 | G9: =G7*Assumptions!$B$8 -> 0.098719801 | H9: =H7*Assumptions!$B$8 -> 0.1677326 | I9: =I7*Assumptions!$B$8 -> 0.24605528 | ... AK9: =AK7*Assumptions!$B$8 -> 6.9275563
A10: Firms at end of month | B10: =B7-B9+B8 -> 1.98 | C10: =C7-C9+C8 -> 1.9602 | D10: =D7-D9+D8 -> 1.940598 | E10: =E7-E9+E8 -> 4.921192 | F10: =F7-F9+F8 -> 9.8719801 | G10: =G7-G9+G8 -> 16.77326 | H10: =H7-H9+H8 -> 24.605528 | I10: =I7-I9+I8 -> 33.359472 | ... AK10: =AK7-AK9+AK8 -> 727.82807
A11: RECURRING REVENUE
A12: Subscription MRR, £ | B12: =(Assumptions!$B$10*(1-Assumptions!$B$8)+B8*Assumptions!$B$6+IF(B4=Assumptions!$B$11,Assumptions!$B$12,0))*IF(OR(B4=13,B4=25),1+Assumptions!$B$9,1) -> 3009.6 | C12: =(B12*(1-Assumptions!$B$8)+C8*Assumptions!$B$6+IF(C4=Assumptions!$B$11,Assumptions!$B$12,0))*IF(OR(C4=13,C4=25),1+Assumptions!$B$9,1) -> 2979.504 | D12: =(C12*(1-Assumptions!$B$8)+D8*Assumptions!$B$6+IF(D4=Assumptions!$B$11,Assumptions!$B$12,0))*IF(OR(D4=13,D4=25),1+Assumptions!$B$9,1) -> 2949.709 | E12: =(D12*(1-Assumptions!$B$8)+E8*Assumptions!$B$6+IF(E4=Assumptions!$B$11,Assumptions!$B$12,0))*IF(OR(E4=13,E4=25),1+Assumptions!$B$9,1) -> 6370.2119 | F12: =(E12*(1-Assumptions!$B$8)+F8*Assumptions!$B$6+IF(F4=Assumptions!$B$11,Assumptions!$B$12,0))*IF(OR(F4=13,F4=25),1+Assumptions!$B$9,1) -> 12056.51 | G12: =(F12*(1-Assumptions!$B$8)+G8*Assumptions!$B$6+IF(G4=Assumptions!$B$11,Assumptions!$B$12,0))*IF(OR(G4=13,G4=25),1+Assumptions!$B$9,1) -> 19985.945 | H12: =(G12*(1-Assumptions!$B$8)+H8*Assumptions!$B$6+IF(H4=Assumptions!$B$11,Assumptions!$B$12,0))*IF(OR(H4=13,H4=25),1+Assumptions!$B$9,1) -> 28986.085 | I12: =(H12*(1-Assumptions!$B$8)+I8*Assumptions!$B$6+IF(I4=Assumptions!$B$11,Assumptions!$B$12,0))*IF(OR(I4=13,I4=25),1+Assumptions!$B$9,1) -> 39046.224 | J12: =(I12*(1-Assumptions!$B$8)+J8*Assumptions!$B$6+IF(J4=Assumptions!$B$11,Assumptions!$B$12,0))*IF(OR(J4=13,J4=25),1+Assumptions!$B$9,1) -> 51305.762 | ... AK12: =(AJ12*(1-Assumptions!$B$8)+AK8*Assumptions!$B$6+IF(AK4=Assumptions!$B$11,Assumptions!$B$12,0))*IF(OR(AK4=13,AK4=25),1+Assumptions!$B$9,1) -> 852663.37
A13: Add-on MRR, £ | B13: =B12*IF(B4<=12,Assumptions!$B$16,IF(B4<=24,Assumptions!$B$17,Assumptions!$B$18)) -> 90.288 | C13: =C12*IF(C4<=12,Assumptions!$B$16,IF(C4<=24,Assumptions!$B$17,Assumptions!$B$18)) -> 89.38512 | D13: =D12*IF(D4<=12,Assumptions!$B$16,IF(D4<=24,Assumptions!$B$17,Assumptions!$B$18)) -> 88.491269 | E13: =E12*IF(E4<=12,Assumptions!$B$16,IF(E4<=24,Assumptions!$B$17,Assumptions!$B$18)) -> 191.10636 | F13: =F12*IF(F4<=12,Assumptions!$B$16,IF(F4<=24,Assumptions!$B$17,Assumptions!$B$18)) -> 361.69529 | G13: =G12*IF(G4<=12,Assumptions!$B$16,IF(G4<=24,Assumptions!$B$17,Assumptions!$B$18)) -> 599.57834 | H13: =H12*IF(H4<=12,Assumptions!$B$16,IF(H4<=24,Assumptions!$B$17,Assumptions!$B$18)) -> 869.58256 | I13: =I12*IF(I4<=12,Assumptions!$B$16,IF(I4<=24,Assumptions!$B$17,Assumptions!$B$18)) -> 1171.3867 | ... AK13: =AK12*IF(AK4<=12,Assumptions!$B$16,IF(AK4<=24,Assumptions!$B$17,Assumptions!$B$18)) -> 119372.87
A14: Total MRR, £ | B14: =B12+B13 -> 3099.888 | C14: =C12+C13 -> 3068.8891 | D14: =D12+D13 -> 3038.2002 | E14: =E12+E13 -> 6561.3182 | F14: =F12+F13 -> 12418.205 | G14: =G12+G13 -> 20585.523 | H14: =H12+H13 -> 29855.668 | I14: =I12+I13 -> 40217.611 | ... AK14: =AK12+AK13 -> 972036.24
A15: ARR run-rate (MRR × 12), £ | B15: =B14*12 -> 37198.656 | C15: =C14*12 -> 36826.669 | D15: =D14*12 -> 36458.403 | E15: =E14*12 -> 78735.819 | F15: =F14*12 -> 149018.46 | G15: =G14*12 -> 247026.28 | H15: =H14*12 -> 358268.01 | I15: =I14*12 -> 482611.33 | ... AK15: =AK14*12 -> 11664435
A16: ONE-OFF
A17: Set-up fees, £ | B17: =B8*Assumptions!$B$7 -> 0 | C17: =C8*Assumptions!$B$7 -> 0 | D17: =D8*Assumptions!$B$7 -> 0 | E17: =E8*Assumptions!$B$7 -> 12000 | F17: =F8*Assumptions!$B$7 -> 20000 | G17: =G8*Assumptions!$B$7 -> 28000 | H17: =H8*Assumptions!$B$7 -> 32000 | I17: =I8*Assumptions!$B$7 -> 36000 | ... AK17: =AK8*Assumptions!$B$7 -> 168000
A18: Total revenue in month, £ | B18: =B14+B17 -> 3099.888 | C18: =C14+C17 -> 3068.8891 | D18: =D14+D17 -> 3038.2002 | E18: =E14+E17 -> 18561.318 | F18: =F14+F17 -> 32418.205 | G18: =G14+G17 -> 48585.523 | H18: =H14+H17 -> 61855.668 | I18: =I14+I17 -> 76217.611 | ... AK18: =AK14+AK17 -> 1140036.2
A19: COSTS
A20: Developers | B20: =IF(B4>=Assumptions!$B$28,Assumptions!$B$27/12,0)+IF(B4>=13,Assumptions!$B$47/12,0) -> 0 | C20: =IF(C4>=Assumptions!$B$28,Assumptions!$B$27/12,0)+IF(C4>=13,Assumptions!$B$47/12,0) -> 0 | D20: =IF(D4>=Assumptions!$B$28,Assumptions!$B$27/12,0)+IF(D4>=13,Assumptions!$B$47/12,0) -> 13333.333 | E20: =IF(E4>=Assumptions!$B$28,Assumptions!$B$27/12,0)+IF(E4>=13,Assumptions!$B$47/12,0) -> 13333.333 | F20: =IF(F4>=Assumptions!$B$28,Assumptions!$B$27/12,0)+IF(F4>=13,Assumptions!$B$47/12,0) -> 13333.333 | G20: =IF(G4>=Assumptions!$B$28,Assumptions!$B$27/12,0)+IF(G4>=13,Assumptions!$B$47/12,0) -> 13333.333 | H20: =IF(H4>=Assumptions!$B$28,Assumptions!$B$27/12,0)+IF(H4>=13,Assumptions!$B$47/12,0) -> 13333.333 | I20: =IF(I4>=Assumptions!$B$28,Assumptions!$B$27/12,0)+IF(I4>=13,Assumptions!$B$47/12,0) -> 13333.333 | ... AK20: =IF(AK4>=Assumptions!$B$28,Assumptions!$B$27/12,0)+IF(AK4>=13,Assumptions!$B$47/12,0) -> 20000
A21: Sales (headcount scales with new firms) | B21: =IF(B4>=Assumptions!$B$29,MAX(1,ROUNDUP(B8/Assumptions!$B$40,0)),0)*Assumptions!$B$41/12 -> 0 | C21: =IF(C4>=Assumptions!$B$29,MAX(1,ROUNDUP(C8/Assumptions!$B$40,0)),0)*Assumptions!$B$41/12 -> 5333.3333 | D21: =IF(D4>=Assumptions!$B$29,MAX(1,ROUNDUP(D8/Assumptions!$B$40,0)),0)*Assumptions!$B$41/12 -> 5333.3333 | E21: =IF(E4>=Assumptions!$B$29,MAX(1,ROUNDUP(E8/Assumptions!$B$40,0)),0)*Assumptions!$B$41/12 -> 5333.3333 | F21: =IF(F4>=Assumptions!$B$29,MAX(1,ROUNDUP(F8/Assumptions!$B$40,0)),0)*Assumptions!$B$41/12 -> 5333.3333 | G21: =IF(G4>=Assumptions!$B$29,MAX(1,ROUNDUP(G8/Assumptions!$B$40,0)),0)*Assumptions!$B$41/12 -> 5333.3333 | H21: =IF(H4>=Assumptions!$B$29,MAX(1,ROUNDUP(H8/Assumptions!$B$40,0)),0)*Assumptions!$B$41/12 -> 5333.3333 | I21: =IF(I4>=Assumptions!$B$29,MAX(1,ROUNDUP(I8/Assumptions!$B$40,0)),0)*Assumptions!$B$41/12 -> 10666.667 | ... AK21: =IF(AK4>=Assumptions!$B$29,MAX(1,ROUNDUP(AK8/Assumptions!$B$40,0)),0)*Assumptions!$B$41/12 -> 32000
A22: Integrations | B22: =IF(AND(B4>=3,B4<=12),Assumptions!$B$30/10,0) -> 0 | C22: =IF(AND(C4>=3,C4<=12),Assumptions!$B$30/10,0) -> 0 | D22: =IF(AND(D4>=3,D4<=12),Assumptions!$B$30/10,0) -> 5000 | E22: =IF(AND(E4>=3,E4<=12),Assumptions!$B$30/10,0) -> 5000 | F22: =IF(AND(F4>=3,F4<=12),Assumptions!$B$30/10,0) -> 5000 | G22: =IF(AND(G4>=3,G4<=12),Assumptions!$B$30/10,0) -> 5000 | H22: =IF(AND(H4>=3,H4<=12),Assumptions!$B$30/10,0) -> 5000 | I22: =IF(AND(I4>=3,I4<=12),Assumptions!$B$30/10,0) -> 5000 | ... AK22: =IF(AND(AK4>=3,AK4<=12),Assumptions!$B$30/10,0) -> 0
A23: Marketing | B23: =IF(B4<=12,IF(B4>=Assumptions!$B$33,Assumptions!$B$32/12,0),B8*Assumptions!$B$48) -> 0 | C23: =IF(C4<=12,IF(C4>=Assumptions!$B$33,Assumptions!$B$32/12,0),C8*Assumptions!$B$48) -> 0 | D23: =IF(D4<=12,IF(D4>=Assumptions!$B$33,Assumptions!$B$32/12,0),D8*Assumptions!$B$48) -> 30000 | E23: =IF(E4<=12,IF(E4>=Assumptions!$B$33,Assumptions!$B$32/12,0),E8*Assumptions!$B$48) -> 30000 | F23: =IF(F4<=12,IF(F4>=Assumptions!$B$33,Assumptions!$B$32/12,0),F8*Assumptions!$B$48) -> 30000 | G23: =IF(G4<=12,IF(G4>=Assumptions!$B$33,Assumptions!$B$32/12,0),G8*Assumptions!$B$48) -> 30000 | H23: =IF(H4<=12,IF(H4>=Assumptions!$B$33,Assumptions!$B$32/12,0),H8*Assumptions!$B$48) -> 30000 | I23: =IF(I4<=12,IF(I4>=Assumptions!$B$33,Assumptions!$B$32/12,0),I8*Assumptions!$B$48) -> 30000 | ... AK23: =IF(AK4<=12,IF(AK4>=Assumptions!$B$33,Assumptions!$B$32/12,0),AK8*Assumptions!$B$48) -> 63000
A24: Onboarding and support (scales with volume) | B24: =IF(B4>=Assumptions!$B$35,Assumptions!$B$34/12,0)+IF(B4>=Assumptions!$B$35,MAX(0,ROUNDUP(MAX(0,B8-Assumptions!$B$43)/Assumptions!$B$42,0)-1),0)*Assumptions!$B$44/12+IF(B4>=13,ROUNDUP(B7/Assumptions!$B$45,0)*Assumptions!$B$46/12,0) -> 0 | C24: =IF(C4>=Assumptions!$B$35,Assumptions!$B$34/12,0)+IF(C4>=Assumptions!$B$35,MAX(0,ROUNDUP(MAX(0,C8-Assumptions!$B$43)/Assumptions!$B$42,0)-1),0)*Assumptions!$B$44/12+IF(C4>=13,ROUNDUP(C7/Assumptions!$B$45,0)*Assumptions!$B$46/12,0) -> 0 | D24: =IF(D4>=Assumptions!$B$35,Assumptions!$B$34/12,0)+IF(D4>=Assumptions!$B$35,MAX(0,ROUNDUP(MAX(0,D8-Assumptions!$B$43)/Assumptions!$B$42,0)-1),0)*Assumptions!$B$44/12+IF(D4>=13,ROUNDUP(D7/Assumptions!$B$45,0)*Assumptions!$B$46/12,0) -> 0 | E24: =IF(E4>=Assumptions!$B$35,Assumptions!$B$34/12,0)+IF(E4>=Assumptions!$B$35,MAX(0,ROUNDUP(MAX(0,E8-Assumptions!$B$43)/Assumptions!$B$42,0)-1),0)*Assumptions!$B$44/12+IF(E4>=13,ROUNDUP(E7/Assumptions!$B$45,0)*Assumptions!$B$46/12,0) -> 3333.3333 | F24: =IF(F4>=Assumptions!$B$35,Assumptions!$B$34/12,0)+IF(F4>=Assumptions!$B$35,MAX(0,ROUNDUP(MAX(0,F8-Assumptions!$B$43)/Assumptions!$B$42,0)-1),0)*Assumptions!$B$44/12+IF(F4>=13,ROUNDUP(F7/Assumptions!$B$45,0)*Assumptions!$B$46/12,0) -> 3333.3333 | G24: =IF(G4>=Assumptions!$B$35,Assumptions!$B$34/12,0)+IF(G4>=Assumptions!$B$35,MAX(0,ROUNDUP(MAX(0,G8-Assumptions!$B$43)/Assumptions!$B$42,0)-1),0)*Assumptions!$B$44/12+IF(G4>=13,ROUNDUP(G7/Assumptions!$B$45,0)*Assumptions!$B$46/12,0) -> 3333.3333 | H24: =IF(H4>=Assumptions!$B$35,Assumptions!$B$34/12,0)+IF(H4>=Assumptions!$B$35,MAX(0,ROUNDUP(MAX(0,H8-Assumptions!$B$43)/Assumptions!$B$42,0)-1),0)*Assumptions!$B$44/12+IF(H4>=13,ROUNDUP(H7/Assumptions!$B$45,0)*Assumptions!$B$46/12,0) -> 3333.3333 | I24: =IF(I4>=Assumptions!$B$35,Assumptions!$B$34/12,0)+IF(I4>=Assumptions!$B$35,MAX(0,ROUNDUP(MAX(0,I8-Assumptions!$B$43)/Assumptions!$B$42,0)-1),0)*Assumptions!$B$44/12+IF(I4>=13,ROUNDUP(I7/Assumptions!$B$45,0)*Assumptions!$B$46/12,0) -> 3333.3333 | ... AK24: =IF(AK4>=Assumptions!$B$35,Assumptions!$B$34/12,0)+IF(AK4>=Assumptions!$B$35,MAX(0,ROUNDUP(MAX(0,AK8-Assumptions!$B$43)/Assumptions!$B$42,0)-1),0)*Assumptions!$B$44/12+IF(AK4>=13,ROUNDUP(AK7/Assumptions!$B$45,0)*Assumptions!$B$46/12,0) -> 46666.667
A25: Azure hosting | B25: =MAX(Assumptions!$B$21,B10*Assumptions!$B$20) -> 500 | C25: =MAX(Assumptions!$B$21,C10*Assumptions!$B$20) -> 500 | D25: =MAX(Assumptions!$B$21,D10*Assumptions!$B$20) -> 500 | E25: =MAX(Assumptions!$B$21,E10*Assumptions!$B$20) -> 500 | F25: =MAX(Assumptions!$B$21,F10*Assumptions!$B$20) -> 500 | G25: =MAX(Assumptions!$B$21,G10*Assumptions!$B$20) -> 670.93041 | H25: =MAX(Assumptions!$B$21,H10*Assumptions!$B$20) -> 984.22111 | I25: =MAX(Assumptions!$B$21,I10*Assumptions!$B$20) -> 1334.3789 | ... AK25: =MAX(Assumptions!$B$21,AK10*Assumptions!$B$20) -> 29113.123
A26: Legal, finance, contingency | B26: =Assumptions!$B$37 -> 5500 | C26: =Assumptions!$B$37 -> 5500 | D26: =Assumptions!$B$37 -> 5500 | E26: =Assumptions!$B$37 -> 5500 | F26: =Assumptions!$B$37 -> 5500 | G26: =Assumptions!$B$37 -> 5500 | H26: =Assumptions!$B$37 -> 5500 | I26: =Assumptions!$B$37 -> 5500 | ... AK26: =Assumptions!$B$37 -> 5500
A27: Founder salary | B27: =Assumptions!$B$38/12 -> 4000 | C27: =Assumptions!$B$38/12 -> 4000 | D27: =Assumptions!$B$38/12 -> 4000 | E27: =Assumptions!$B$38/12 -> 4000 | F27: =Assumptions!$B$38/12 -> 4000 | G27: =Assumptions!$B$38/12 -> 4000 | H27: =Assumptions!$B$38/12 -> 4000 | I27: =Assumptions!$B$38/12 -> 4000 | ... AK27: =Assumptions!$B$38/12 -> 4000
A28: Total costs, £ | B28: =SUM(B20:B27) -> 10000 | C28: =SUM(C20:C27) -> 15333.333 | D28: =SUM(D20:D27) -> 63666.667 | E28: =SUM(E20:E27) -> 67000 | F28: =SUM(F20:F27) -> 67000 | G28: =SUM(G20:G27) -> 67170.93 | H28: =SUM(H20:H27) -> 67484.221 | I28: =SUM(I20:I27) -> 73167.712 | ... AK28: =SUM(AK20:AK27) -> 200279.79
A29: CASH
A30: Net cash flow in month, £ | B30: =B18-B28 -> -6900.112 | C30: =C18-C28 -> -12264.444 | D30: =D18-D28 -> -60628.466 | E30: =E18-E28 -> -48438.682 | F30: =F18-F28 -> -34581.795 | G30: =G18-G28 -> -18585.407 | H30: =H18-H28 -> -5628.5533 | I30: =I18-I28 -> 3049.8989 | ... AK30: =AK18-AK28 -> 939756.45
A31: Round received, £ | B31: =IF(B4=Assumptions!$B$23,Assumptions!$B$25,0) -> 1000000 | C31: =IF(C4=Assumptions!$B$23,Assumptions!$B$25,0) -> 0 | D31: =IF(D4=Assumptions!$B$23,Assumptions!$B$25,0) -> 0 | E31: =IF(E4=Assumptions!$B$23,Assumptions!$B$25,0) -> 0 | F31: =IF(F4=Assumptions!$B$23,Assumptions!$B$25,0) -> 0 | G31: =IF(G4=Assumptions!$B$23,Assumptions!$B$25,0) -> 0 | H31: =IF(H4=Assumptions!$B$23,Assumptions!$B$25,0) -> 0 | I31: =IF(I4=Assumptions!$B$23,Assumptions!$B$25,0) -> 0 | ... AK31: =IF(AK4=Assumptions!$B$23,Assumptions!$B$25,0) -> 0
A32: Cash balance at end of month, £ | B32: =B30+B31 -> 993099.89 | C32: =B32+C30+C31 -> 980835.44 | D32: =C32+D30+D31 -> 920206.98 | E32: =D32+E30+E31 -> 871768.3 | F32: =E32+F30+F31 -> 837186.5 | G32: =F32+G30+G31 -> 818601.09 | H32: =G32+H30+H31 -> 812972.54 | I32: =H32+I30+I31 -> 816022.44 | J32: =I32+J30+J31 -> 835939.67 | ... AK32: =AJ32+AK30+AK31 -> 12719148
